Workbook

Sheet 可交换债数据
A1: 日期 | B1: 证券代码 | C1: 证券名称 | D1: 正股代码 | E1: 正股简称 | F1: 成交金额（万元） | G1: 成交量(张) | H1: 成交均价（净价） | I1: 票面利率(当期参考%) | J1: 补偿利率（%） | K1: 转股价格(元) | L1: 正股收盘价(元) | M1: 中证含权估值(元) | N1: 期权价值(元) | O1: 中证不含权估值(元)
A2: =TEXT([1]sheet1!$B$3,"yyyy-mm-dd") -> 2026-08-17 | B2: =IF(LEN(TRIM([2]可交债!A2))=6,TRIM([2]可交债!A2)&".SZ",TRIM([2]可交债!A2)) -> 137116.SH | C2: =IFERROR(VLOOKUP(LEFT($B2,6)&"*",[2]可交债!$A:$H,2,FALSE),"") -> 20三一EB | D2: =IFERROR(VLOOKUP(LEFT($B2,6)&"*",[2]可交债!$A:$H,3,FALSE),"") -> 600031.SH | E2: =IFERROR(VLOOKUP(LEFT($B2,6)&"*",[2]可交债!$A:$H,4,FALSE),"") -> 三一重工 | F2: =SUMPRODUCT((LEFT(TRIM('[3]现券交易信息（逐笔）'!$B$2:$B$500),6)=LEFT($B2,6))*(IFERROR(--SUBSTITUTE('[3]现券交易信息（逐笔）'!$G$2:$G$500,",",""),0)))+SUMIF([1]sheet1!$D$2:$D$500,LEFT($B2,6)&"*",[1]sheet1!$M$2:$M$500) -> 0 | G2: =SUMPRODUCT((LEFT(TRIM('[3]现券交易信息（逐笔）'!$B$2:$B$500),6)=LEFT($B2,6))*(IFERROR(--SUBSTITUTE('[3]现券交易信息（逐笔）'!$F$2:$F$500,",",""),0)*100))+SUMIF([1]sheet1!$D$2:$D$500,LEFT($B2,6)&"*",[1]sheet1!$L$2:$L$500)*100 -> 0 | H2: =IF(G2=0,"",ROUND(F2*10000/G2,4)) | I2: =IFERROR(VLOOKUP(LEFT($B2,6)&"*",[2]可交债!$A:$H,5,FALSE),"") -> 1.5 | J2: =IFERROR(VLOOKUP(LEFT($B2,6)&"*",[2]可交债!$A:$H,6,FALSE),"") -> 3 | K2: =IFERROR(VLOOKUP(LEFT($B2,6)&"*",[2]可交债!$A:$H,7,FALSE),"") -> 25.72 | L2: =IFERROR(VLOOKUP(LEFT($B2,6)&"*",[2]可交债!$A:$H,8,FALSE),"") -> 18.7 | M2: =IFERROR(VLOOKUP(LEFT($B2,6),[4]中证可交换债券估值!$A:$H,5,FALSE),"") -> 102.8553 | N2: =IFERROR(VLOOKUP(LEFT($B2,6),[4]中证可交换债券估值!$A:$H,6,FALSE),"") -> 0.0002 | O2: =IFERROR(VLOOKUP(LEFT($B2,6),[4]中证可交换债券估值!$A:$H,7,FALSE),"") -> 102.8551
A3: =TEXT([1]sheet1!$B$3,"yyyy-mm-dd") -> 2026-08-17 | B3: =IF(LEN(TRIM([2]可交债!A3))=6,TRIM([2]可交债!A3)&".SZ",TRIM([2]可交债!A3)) -> 137139.SH | C3: =IFERROR(VLOOKUP(LEFT($B3,6)&"*",[2]可交债!$A:$H,2,FALSE),"") -> 22YN01EB | D3: =IFERROR(VLOOKUP(LEFT($B3,6)&"*",[2]可交债!$A:$H,3,FALSE),"") -> 600900.SH | E3: =IFERROR(VLOOKUP(LEFT($B3,6)&"*",[2]可交债!$A:$H,4,FALSE),"") -> 长江电力 | F3: =SUMPRODUCT((LEFT(TRIM('[3]现券交易信息（逐笔）'!$B$2:$B$500),6)=LEFT($B3,6))*(IFERROR(--SUBSTITUTE('[3]现券交易信息（逐笔）'!$G$2:$G$500,",",""),0)))+SUMIF([1]sheet1!$D$2:$D$500,LEFT($B3,6)&"*",[1]sheet1!$M$2:$M$500) -> 0 | G3: =SUMPRODUCT((LEFT(TRIM('[3]现券交易信息（逐笔）'!$B$2:$B$500),6)=LEFT($B3,6))*(IFERROR(--SUBSTITUTE('[3]现券交易信息（逐笔）'!$F$2:$F$500,",",""),0)*100))+SUMIF([1]sheet1!$D$2:$D$500,LEFT($B3,6)&"*",[1]sheet1!$L$2:$L$500)*100 -> 0 | H3: =IF(G3=0,"",ROUND(F3*10000/G3,4)) | I3: =IFERROR(VLOOKUP(LEFT($B3,6)&"*",[2]可交债!$A:$H,5,FALSE),"") -> 4 | J3: =IFERROR(VLOOKUP(LEFT($B3,6)&"*",[2]可交债!$A:$H,6,FALSE),"") -> 0 | K3: =IFERROR(VLOOKUP(LEFT($B3,6)&"*",[2]可交债!$A:$H,7,FALSE),"") -> 53.2 | L3: =IFERROR(VLOOKUP(LEFT($B3,6)&"*",[2]可交债!$A:$H,8,FALSE),"") -> 27.96 | M3: =IFERROR(VLOOKUP(LEFT($B3,6),[4]中证可交换债券估值!$A:$H,5,FALSE),"") -> 102.968 | N3: =IFERROR(VLOOKUP(LEFT($B3,6),[4]中证可交换债券估值!$A:$H,6,FALSE),"") -> 0 | O3: =IFERROR(VLOOKUP(LEFT($B3,6),[4]中证可交换债券估值!$A:$H,7,FALSE),"") -> 102.968
A4: =TEXT([1]sheet1!$B$3,"yyyy-mm-dd") -> 2026-08-17 | B4: =IF(LEN(TRIM([2]可交债!A4))=6,TRIM([2]可交债!A4)&".SZ",TRIM([2]可交债!A4)) -> 137148.SH | C4: =IFERROR(VLOOKUP(LEFT($B4,6)&"*",[2]可交债!$A:$H,2,FALSE),"") -> 22YN02EB | D4: =IFERROR(VLOOKUP(LEFT($B4,6)&"*",[2]可交债!$A:$H,3,FALSE),"") -> 600900.SH | E4: =IFERROR(VLOOKUP(LEFT($B4,6)&"*",[2]可交债!$A:$H,4,FALSE),"") -> 长江电力 | F4: =SUMPRODUCT((LEFT(TRIM('[3]现券交易信息（逐笔）'!$B$2:$B$500),6)=LEFT($B4,6))*(IFERROR(--SUBSTITUTE('[3]现券交易信息（逐笔）'!$G$2:$G$500,",",""),0)))+SUMIF([1]sheet1!$D$2:$D$500,LEFT($B4,6)&"*",[1]sheet1!$M$2:$M$500) -> 0 | G4: =SUMPRODUCT((LEFT(TRIM('[3]现券交易信息（逐笔）'!$B$2:$B$500),6)=LEFT($B4,6))*(IFERROR(--SUBSTITUTE('[3]现券交易信息（逐笔）'!$F$2:$F$500,",",""),0)*100))+SUMIF([1]sheet1!$D$2:$D$500,LEFT($B4,6)&"*",[1]sheet1!$L$2:$L$500)*100 -> 0 | H4: =IF(G4=0,"",ROUND(F4*10000/G4,4)) | I4: =IFERROR(VLOOKUP(LEFT($B4,6)&"*",[2]可交债!$A:$H,5,FALSE),"") -> 3.99 | J4: =IFERROR(VLOOKUP(LEFT($B4,6)&"*",[2]可交债!$A:$H,6,FALSE),"") -> 0 | K4: =IFERROR(VLOOKUP(LEFT($B4,6)&"*",[2]可交债!$A:$H,7,FALSE),"") -> 52.85 | L4: =IFERROR(VLOOKUP(LEFT($B4,6)&"*",[2]可交债!$A:$H,8,FALSE),"") -> 27.96 | M4: =IFERROR(VLOOKUP(LEFT($B4,6),[4]中证可交换债券估值!$A:$H,5,FALSE),"") -> 102.8367 | N4: =IFERROR(VLOOKUP(LEFT($B4,6),[4]中证可交换债券估值!$A:$H,6,FALSE),"") -> 0 | O4: =IFERROR(VLOOKUP(LEFT($B4,6),[4]中证可交换债券估值!$A:$H,7,FALSE),"") -> 102.8367
A5: =TEXT([1]sheet1!$B$3,"yyyy-mm-dd") -> 2026-08-17 | B5: =IF(LEN(TRIM([2]可交债!A5))=6,TRIM([2]可交债!A5)&".SZ",TRIM([2]可交债!A5)) -> 137180.SH | C5: =IFERROR(VLOOKUP(LEFT($B5,6)&"*",[2]可交债!$A:$H,2,FALSE),"") -> 23MYEB1 | D5: =IFERROR(VLOOKUP(LEFT($B5,6)&"*",[2]可交债!$A:$H,3,FALSE),"") -> 601615.SH | E5: =IFERROR(VLOOKUP(LEFT($B5,6)&"*",[2]可交债!$A:$H,4,FALSE),"") -> 明阳智能 | F5: =SUMPRODUCT((LEFT(TRIM('[3]现券交易信息（逐笔）'!$B$2:$B$500),6)=LEFT($B5,6))*(IFERROR(--SUBSTITUTE('[3]现券交易信息（逐笔）'!$G$2:$G$500,",",""),0)))+SUMIF([1]sheet1!$D$2:$D$500,LEFT($B5,6)&"*",[1]sheet1!$M$2:$M$500) -> 0 | G5: =SUMPRODUCT((LEFT(TRIM('[3]现券交易信息（逐笔）'!$B$2:$B$500),6)=LEFT($B5,6))*(IFERROR(--SUBSTITUTE('[3]现券交易信息（逐笔）'!$F$2:$F$500,",",""),0)*100))+SUMIF([1]sheet1!$D$2:$D$500,LEFT($B5,6)&"*",[1]sheet1!$L$2:$L$500)*100 -> 0 | H5: =IF(G5=0,"",ROUND(F5*10000/G5,4)) | I5: =IFERROR(VLOOKUP(LEFT($B5,6)&"*",[2]可交债!$A:$H,5,FALSE),"") -> 2 | J5: =IFERROR(VLOOKUP(LEFT($B5,6)&"*",[2]可交债!$A:$H,6,FALSE),"") -> 4.5 | K5: =IFERROR(VLOOKUP(LEFT($B5,6)&"*",[2]可交债!$A:$H,7,FALSE),"") -> 24.24 | L5: =IFERROR(VLOOKUP(LEFT($B5,6)&"*",[2]可交债!$A:$H,8,FALSE),"") -> 11.64 | M5: =IFERROR(VLOOKUP(LEFT($B5,6),[4]中证可交换债券估值!$A:$H,5,FALSE),"") -> 106.2698 | N5: =IFERROR(VLOOKUP(LEFT($B5,6),[4]中证可交换债券估值!$A:$H,6,FALSE),"") -> 0 | O5: =IFERROR(VLOOKUP(LEFT($B5,6),[4]中证可交换债券估值!$A:$H,7,FALSE),"") -> 106.2698
A6: =TEXT([1]sheet1!$B$3,"yyyy-mm-dd") -> 2026-08-17 | B6: =IF(LEN(TRIM([2]可交债!A6))=6,TRIM([2]可交债!A6)&".SZ",TRIM([2]可交债!A6)) -> 137170.SH | C6: =IFERROR(VLOOKUP(LEFT($B6,6)&"*",[2]可交债!$A:$H,2,FALSE),"") -> 23YN01EB | D6: =IFERROR(VLOOKUP(LEFT($B6,6)&"*",[2]可交债!$A:$H,3,FALSE),"") -> 600900.SH | E6: =IFERROR(VLOOKUP(LEFT($B6,6)&"*",[2]可交债!$A:$H,4,FALSE),"") -> 长江电力 | F6: =SUMPRODUCT((LEFT(TRIM('[3]现券交易信息（逐笔）'!$B$2:$B$500),6)=LEFT($B6,6))*(IFERROR(--SUBSTITUTE('[3]现券交易信息（逐笔）'!$G$2:$G$500,",",""),0)))+SUMIF([1]sheet1!$D$2:$D$500,LEFT($B6,6)&"*",[1]sheet1!$M$2:$M$500) -> 0 | G6: =SUMPRODUCT((LEFT(TRIM('[3]现券交易信息（逐笔）'!$B$2:$B$500),6)=LEFT($B6,6))*(IFERROR(--SUBSTITUTE('[3]现券交易信息（逐笔）'!$F$2:$F$500,",",""),0)*100))+SUMIF([1]sheet1!$D$2:$D$500,LEFT($B6,6)&"*",[1]sheet1!$L$2:$L$500)*100 -> 0 | H6: =IF(G6=0,"",ROUND(F6*10000/G6,4)) | I6: =IFERROR(VLOOKUP(LEFT($B6,6)&"*",[2]可交债!$A:$H,5,FALSE),"") -> 4.3 | J6: =IFERROR(VLOOKUP(LEFT($B6,6)&"*",[2]可交债!$A:$H,6,FALSE),"") -> 0 | K6: =IFERROR(VLOOKUP(LEFT($B6,6)&"*",[2]可交债!$A:$H,7,FALSE),"") -> 48.95 | L6: =IFERROR(VLOOKUP(LEFT($B6,6)&"*",[2]可交债!$A:$H,8,FALSE),"") -> 27.96 | M6: =IFERROR(VLOOKUP(LEFT($B6,6),[4]中证可交换债券估值!$A:$H,5,FALSE),"") -> 105.5947 | N6: =IFERROR(VLOOKUP(LEFT($B6,6),[4]中证可交换债券估值!$A:$H,6,FALSE),"") -> 0.0016 | O6: =IFERROR(VLOOKUP(LEFT($B6,6),[4]中证可交换债券估值!$A:$H,7,FALSE),"") -> 105.5931
A7: =TEXT([1]sheet1!$B$3,"yyyy-mm-dd") -> 2026-08-17 | B7: =IF(LEN(TRIM([2]可交债!A7))=6,TRIM([2]可交债!A7)&".SZ",TRIM([2]可交债!A7)) -> 117216.SZ | C7: =IFERROR(VLOOKUP(LEFT($B7,6)&"*",[2]可交债!$A:$H,2,FALSE),"") -> 23航发EB | D7: =IFERROR(VLOOKUP(LEFT($B7,6)&"*",[2]可交债!$A:$H,3,FALSE),"") -> 000738.SZ | E7: =IFERROR(VLOOKUP(LEFT($B7,6)&"*",[2]可交债!$A:$H,4,FALSE),"") -> 航发控制 | F7: =SUMPRODUCT((LEFT(TRIM('[3]现券交易信息（逐笔）'!$B$2:$B$500),6)=LEFT($B7,6))*(IFERROR(--SUBSTITUTE('[3]现券交易信息（逐笔）'!$G$2:$G$500,",",""),0)))+SUMIF([1]sheet1!$D$2:$D$500,LEFT($B7,6)&"*",[1]sheet1!$M$2:$M$500) -> 0 | G7: =SUMPRODUCT((LEFT(TRIM('[3]现券交易信息（逐笔）'!$B$2:$B$500),6)=LEFT($B7,6))*(IFERROR(--SUBSTITUTE('[3]现券交易信息（逐笔）'!$F$2:$F$500,",",""),0)*100))+SUMIF([1]sheet1!$D$2:$D$500,LEFT($B7,6)&"*",[1]sheet1!$L$2:$L$500)*100 -> 0 | H7: =IF(G7=0,"",ROUND(F7*10000/G7,4)) | I7: =IFERROR(VLOOKUP(LEFT($B7,6)&"*",[2]可交债!$A:$H,5,FALSE),"") -> 0.5 | J7: =IFERROR(VLOOKUP(LEFT($B7,6)&"*",[2]可交债!$A:$H,6,FALSE),"") -> 6 | K7: =IFERROR(VLOOKUP(LEFT($B7,6)&"*",[2]可交债!$A:$H,7,FALSE),"") -> 26.58 | L7: =IFERROR(VLOOKUP(LEFT($B7,6)&"*",[2]可交债!$A:$H,8,FALSE),"") -> 18.71 | M7: =IFERROR(VLOOKUP(LEFT($B7,6),[4]中证可交换债券估值!$A:$H,5,FALSE),"") -> 106.2604 | N7: =IFERROR(VLOOKUP(LEFT($B7,6),[4]中证可交换债券估值!$A:$H,6,FALSE),"") -> 0.2205 | O7: =IFERROR(VLOOKUP(LEFT($B7,6),[4]中证可交换债券估值!$A:$H,7,FALSE),"") -> 106.0399
A8: =TEXT([1]sheet1!$B$3,"yyyy-mm-dd") -> 2026-08-17 | B8: =IF(LEN(TRIM([2]可交债!A8))=6,TRIM([2]可交债!A8)&".SZ",TRIM([2]可交债!A8)) -> 117210.SZ | C8: =IFERROR(VLOOKUP(LEFT($B8,6)&"*",[2]可交债!$A:$H,2,FALSE),"") -> 23建安E1 | D8: =IFERROR(VLOOKUP(LEFT($B8,6)&"*",[2]可交债!$A:$H,3,FALSE),"") -> 000728.SZ | E8: =IFERROR(VLOOKUP(LEFT($B8,6)&"*",[2]可交债!$A:$H,4,FALSE),"") -> 国元证券 | F8: =SUMPRODUCT((LEFT(TRIM('[3]现券交易信息（逐笔）'!$B$2:$B$500),6)=LEFT($B8,6))*(IFERROR(--SUBSTITUTE('[3]现券交易信息（逐笔）'!$G$2:$G$500,",",""),0)))+SUMIF([1]sheet1!$D$2:$D$500,LEFT($B8,6)&"*",[1]sheet1!$M$2:$M$500) -> 0 | G8: =SUMPRODUCT((LEFT(TRIM('[3]现券交易信息（逐笔）'!$B$2:$B$500),6)=LEFT($B8,6))*(IFERROR(--SUBSTITUTE('[3]现券交易信息（逐笔）'!$F$2:$F$500,",",""),0)*100))+SUMIF([1]sheet1!$D$2:$D$500,LEFT($B8,6)&"*",[1]sheet1!$L$2:$L$500)*100 -> 0 | H8: =IF(G8=0,"",ROUND(F8*10000/G8,4)) | I8: =IFERROR(VLOOKUP(LEFT($B8,6)&"*",[2]可交债!$A:$H,5,FALSE),"") -> 1.5 | J8: =IFERROR(VLOOKUP(LEFT($B8,6)&"*",[2]可交债!$A:$H,6,FALSE),"") -> 6.5 | K8: =IFERROR(VLOOKUP(LEFT($B8,6)&"*",[2]可交债!$A:$H,7,FALSE),"") -> 9.56 | L8: =IFERROR(VLOOKUP(LEFT($B8,6)&"*",[2]可交债!$A:$H,8,FALSE),"") -> 7.16 | M8: =IFERROR(VLOOKUP(LEFT($B8,6),[4]中证可交换债券估值!$A:$H,5,FALSE),"") -> 107.9383 | N8: =IFERROR(VLOOKUP(LEFT($B8,6),[4]中证可交换债券估值!$A:$H,6,FALSE),"") -> 0 | O8: =IFERROR(VLOOKUP(LEFT($B8,6),[4]中证可交换债券估值!$A:$H,7,FALSE),"") -> 107.9383
A9: =TEXT([1]sheet1!$B$3,"yyyy-mm-dd") -> 2026-08-17 | B9: =IF(LEN(TRIM([2]可交债!A9))=6,TRIM([2]可交债!A9)&".SZ",TRIM([2]可交债!A9)) -> 137181.SH | C9: =IFERROR(VLOOKUP(LEFT($B9,6)&"*",[2]可交债!$A:$H,2,FALSE),"") -> 23杰瑞EB | D9: =IFERROR(VLOOKUP(LEFT($B9,6)&"*",[2]可交债!$A:$H,3,FALSE),"") -> 600764.SH | E9: =IFERROR(VLOOKUP(LEFT($B9,6)&"*",[2]可交债!$A:$H,4,FALSE),"") -> 中国海防 | F9: =SUMPRODUCT((LEFT(TRIM('[3]现券交易信息（逐笔）'!$B$2:$B$500),6)=LEFT($B9,6))*(IFERROR(--SUBSTITUTE('[3]现券交易信息（逐笔）'!$G$2:$G$500,",",""),0)))+SUMIF([1]sheet1!$D$2:$D$500,LEFT($B9,6)&"*",[1]sheet1!$M$2:$M$500) -> 0 | G9: =SUMPRODUCT((LEFT(TRIM('[3]现券交易信息（逐笔）'!$B$2:$B$500),6)=LEFT($B9,6))*(IFERROR(--SUBSTITUTE('[3]现券交易信息（逐笔）'!$F$2:$F$500,",",""),0)*100))+SUMIF([1]sheet1!$D$2:$D$500,LEFT($B9,6)&"*",[1]sheet1!$L$2:$L$500)*100 -> 0 | H9: =IF(G9=0,"",ROUND(F9*10000/G9,4)) | I9: =IFERROR(VLOOKUP(LEFT($B9,6)&"*",[2]可交债!$A:$H,5,FALSE),"") -> 0.01 | J9: =IFERROR(VLOOKUP(LEFT($B9,6)&"*",[2]可交债!$A:$H,6,FALSE),"") -> 0 | K9: =IFERROR(VLOOKUP(LEFT($B9,6)&"*",[2]可交债!$A:$H,7,FALSE),"") -> 27.67 | L9: =IFERROR(VLOOKUP(LEFT($B9,6)&"*",[2]可交债!$A:$H,8,FALSE),"") -> 18.24 | M9: =IFERROR(VLOOKUP(LEFT($B9,6),[4]中证可交换债券估值!$A:$H,5,FALSE),"") -> 100.0587 | N9: =IFERROR(VLOOKUP(LEFT($B9,6),[4]中证可交换债券估值!$A:$H,6,FALSE),"") -> 0.2175 | O9: =IFERROR(VLOOKUP(LEFT($B9,6),[4]中证可交换债券估值!$A:$H,7,FALSE),"") -> 99.8412
A10: =TEXT([1]sheet1!$B$3,"yyyy-mm-dd") -> 2026-08-17 | B10: =IF(LEN(TRIM([2]可交债!A10))=6,TRIM([2]可交债!A10)&".SZ",TRIM([2]可交债!A10)) -> 117212.SZ | C10: =IFERROR(VLOOKUP(LEFT($B10,6)&"*",[2]可交债!$A:$H,2,FALSE),"") -> 23京源EB | D10: =IFERROR(VLOOKUP(LEFT($B10,6)&"*",[2]可交债!$A:$H,3,FALSE),"") -> 000821.SZ | E10: =IFERROR(VLOOKUP(LEFT($B10,6)&"*",[2]可交债!$A:$H,4,FALSE),"") -> ST京机 | F10: =SUMPRODUCT((LEFT(TRIM('[3]现券交易信息（逐笔）'!$B$2:$B$500),6)=LEFT($B10,6))*(IFERROR(--SUBSTITUTE('[3]现券交易信息（逐笔）'!$G$2:$G$500,",",""),0)))+SUMIF([1]sheet1!$D$2:$D$500,LEFT($B10,6)&"*",[1]sheet1!$M$2:$M$500) -> 0 | G10: =SUMPRODUCT((LEFT(TRIM('[3]现券交易信息（逐笔）'!$B$2:$B$500),6)=LEFT($B10,6))*(IFERROR(--SUBSTITUTE('[3]现券交易信息（逐笔）'!$F$2:$F$500,",",""),0)*100))+SUMIF([1]sheet1!$D$2:$D$500,LEFT($B10,6)&"*",[1]sheet1!$L$2:$L$500)*100 -> 0 | H10: =IF(G10=0,"",ROUND(F10*10000/G10,4)) | I10: =IFERROR(VLOOKUP(LEFT($B10,6)&"*",[2]可交债!$A:$H,5,FALSE),"") -> 0.5 | J10: =IFERROR(VLOOKUP(LEFT($B10,6)&"*",[2]可交债!$A:$H,6,FALSE),"") -> 4.5 | K10: =IFERROR(VLOOKUP(LEFT($B10,6)&"*",[2]可交债!$A:$H,7,FALSE),"") -> 14.47 | L10: =IFERROR(VLOOKUP(LEFT($B10,6)&"*",[2]可交债!$A:$H,8,FALSE),"") -> 7.17 | M10: =IFERROR(VLOOKUP(LEFT($B10,6),[4]中证可交换债券估值!$A:$H,5,FALSE),"") -> 105.3421 | N10: =IFERROR(VLOOKUP(LEFT($B10,6),[4]中证可交换债券估值!$A:$H,6,FALSE),"") -> 0.1767 | O10: =IFERROR(VLOOKUP(LEFT($B10,6),[4]中证可交换债券估值!$A:$H,7,FALSE),"") -> 105.1654
A11: =TEXT([1]sheet1!$B$3,"yyyy-mm-dd") -> 2026-08-17 | B11: =IF(LEN(TRIM([2]可交债!A11))=6,TRIM([2]可交债!A11)&".SZ",TRIM([2]可交债!A11)) -> 137183.SH | C11: =IFERROR(VLOOKUP(LEFT($B11,6)&"*",[2]可交债!$A:$H,2,FALSE),"") -> 23潞安EB | D11: =IFERROR(VLOOKUP(LEFT($B11,6)&"*",[2]可交债!$A:$H,3,FALSE),"") -> 601699.SH | E11: =IFERROR(VLOOKUP(LEFT($B11,6)&"*",[2]可交债!$A:$H,4,FALSE),"") -> 潞安环能 | F11: =SUMPRODUCT((LEFT(TRIM('[3]现券交易信息（逐笔）'!$B$2:$B$500),6)=LEFT($B11,6))*(IFERROR(--SUBSTITUTE('[3]现券交易信息（逐笔）'!$G$2:$G$500,",",""),0)))+SUMIF([1]sheet1!$D$2:$D$500,LEFT($B11,6)&"*",[1]sheet1!$M$2:$M$500) -> 0 | G11: =SUMPRODUCT((LEFT(TRIM('[3]现券交易信息（逐笔）'!$B$2:$B$500),6)=LEFT($B11,6))*(IFERROR(--SUBSTITUTE('[3]现券交易信息（逐笔）'!$F$2:$F$500,",",""),0)*100))+SUMIF([1]sheet1!$D$2:$D$500,LEFT($B11,6)&"*",[1]sheet1!$L$2:$L$500)*100 -> 0 | H11: =IF(G11=0,"",ROUND(F11*10000/G11,4)) | I11: =IFERROR(VLOOKUP(LEFT($B11,6)&"*",[2]可交债!$A:$H,5,FALSE),"") -> 0.01 | J11: =IFERROR(VLOOKUP(LEFT($B11,6)&"*",[2]可交债!$A:$H,6,FALSE),"") -> 4.5 | K11: =IFERROR(VLOOKUP(LEFT($B11,6)&"*",[2]可交债!$A:$H,7,FALSE),"") -> 24.91 | L11: =IFERROR(VLOOKUP(LEFT($B11,6)&"*",[2]可交债!$A:$H,8,FALSE),"") -> 16.31 | M11: =IFERROR(VLOOKUP(LEFT($B11,6),[4]中证可交换债券估值!$A:$H,5,FALSE),"") -> 104.2964 | N11: =IFERROR(VLOOKUP(LEFT($B11,6),[4]中证可交换债券估值!$A:$H,6,FALSE),"") -> 0.2468 | O11: =IFERROR(VLOOKUP(LEFT($B11,6),[4]中证可交换债券估值!$A:$H,7,FALSE),"") -> 104.0496
A12: =TEXT([1]sheet1!$B$3,"yyyy-mm-dd") -> 2026-08-17 | B12: =IF(LEN(TRIM([2]可交债!A12))=6,TRIM([2]可交债!A12)&".SZ",TRIM([2]可交债!A12)) -> 137182.SH | C12: =IFERROR(VLOOKUP(LEFT($B12,6)&"*",[2]可交债!$A:$H,2,FALSE),"") -> 23全柴EB | D12: =IFERROR(VLOOKUP(LEFT($B12,6)&"*",[2]可交债!$A:$H,3,FALSE),"") -> 600218.SH | E12: =IFERROR(VLOOKUP(LEFT($B12,6)&"*",[2]可交债!$A:$H,4,FALSE),"") -> 全柴动力 | F12: =SUMPRODUCT((LEFT(TRIM('[3]现券交易信息（逐笔）'!$B$2:$B$500),6)=LEFT($B12,6))*(IFERROR(--SUBSTITUTE('[3]现券交易信息（逐笔）'!$G$2:$G$500,",",""),0)))+SUMIF([1]sheet1!$D$2:$D$500,LEFT($B12,6)&"*",[1]sheet1!$M$2:$M$500) -> 0 | G12: =SUMPRODUCT((LEFT(TRIM('[3]现券交易信息（逐笔）'!$B$2:$B$500),6)=LEFT($B12,6))*(IFERROR(--SUBSTITUTE('[3]现券交易信息（逐笔）'!$F$2:$F$500,",",""),0)*100))+SUMIF([1]sheet1!$D$2:$D$500,LEFT($B12,6)&"*",[1]sheet1!$L$2:$L$500)*100 -> 0 | H12: =IF(G12=0,"",ROUND(F12*10000/G12,4)) | I12: =IFERROR(VLOOKUP(LEFT($B12,6)&"*",[2]可交债!$A:$H,5,FALSE),"") -> 1 | J12: =IFERROR(VLOOKUP(LEFT($B12,6)&"*",[2]可交债!$A:$H,6,FALSE),"") -> 6 | K12: =IFERROR(VLOOKUP(LEFT($B12,6)&"*",[2]可交债!$A:$H,7,FALSE),"") -> 10.74 | L12: =IFERROR(VLOOKUP(LEFT($B12,6)&"*",[2]可交债!$A:$H,8,FALSE),"") -> 7.7 | M12: =IFERROR(VLOOKUP(LEFT($B12,6),[4]中证可交换债券估值!$A:$H,5,FALSE),"") -> 106.6942 | N12: =IFERROR(VLOOKUP(LEFT($B12,6),[4]中证可交换债券估值!$A:$H,6,FALSE),"") -> 0.3445 | O12: =IFERROR(VLOOKUP(LEFT($B12,6),[4]中证可交换债券估值!$A:$H,7,FALSE),"") -> 106.3497
A13: =TEXT([1]sheet1!$B$3,"yyyy-mm-dd") -> 2026-08-17 | B13: =IF(LEN(TRIM([2]可交债!A13))=6,TRIM([2]可交债!A13)&".SZ",TRIM([2]可交债!A13)) -> 137184.SH | C13: =IFERROR(VLOOKUP(LEFT($B13,6)&"*",[2]可交债!$A:$H,2,FALSE),"") -> 24MYEB1 | D13: =IFERROR(VLOOKUP(LEFT($B13,6)&"*",[2]可交债!$A:$H,3,FALSE),"") -> 601615.SH | E13: =IFERROR(VLOOKUP(LEFT($B13,6)&"*",[2]可交债!$A:$H,4,FALSE),"") -> 明阳智能 | F13: =SUMPRODUCT((LEFT(TRIM('[3]现券交易信息（逐笔）'!$B$2:$B$500),6)=LEFT($B13,6))*(IFERROR(--SUBSTITUTE('[3]现券交易信息（逐笔）'!$G$2:$G$500,",",""),0)))+SUMIF([1]sheet1!$D$2:$D$500,LEFT($B13,6)&"*",[1]sheet1!$M$2:$M$500) -> 0 | G13: =SUMPRODUCT((LEFT(TRIM('[3]现券交易信息（逐笔）'!$B$2:$B$500),6)=LEFT($B13,6))*(IFERROR(--SUBSTITUTE('[3]现券交易信息（逐笔）'!$F$2:$F$500,",",""),0)*100))+SUMIF([1]sheet1!$D$2:$D$500,LEFT($B13,6)&"*",[1]sheet1!$L$2:$L$500)*100 -> 0 | H13: =IF(G13=0,"",ROUND(F13*10000/G13,4)) | I13: =IFERROR(VLOOKUP(LEFT($B13,6)&"*",[2]可交债!$A:$H,5,FALSE),"") -> 2 | J13: =IFERROR(VLOOKUP(LEFT($B13,6)&"*",[2]可交债!$A:$H,6,FALSE),"") -> 4.5 | K13: =IFERROR(VLOOKUP(LEFT($B13,6)&"*",[2]可交债!$A:$H,7,FALSE),"") -> 24.24 | L13: =IFERROR(VLOOKUP(LEFT($B13,6)&"*",[2]可交债!$A:$H,8,FALSE),"") -> 11.64 | M13: =IFERROR(VLOOKUP(LEFT($B13,6),[4]中证可交换债券估值!$A:$H,5,FALSE),"") -> 105.9193 | N13: =IFERROR(VLOOKUP(LEFT($B13,6),[4]中证可交换债券估值!$A:$H,6,FALSE),"") -> 0.0993 | O13: =IFERROR(VLOOKUP(LEFT($B13,6),[4]中证可交换债券估值!$A:$H,7,FALSE),"") -> 105.82
... A20: =TEXT([1]sheet1!$B$3,"yyyy-mm-dd") -> 2026-08-17 | B20: =IF(LEN(TRIM([2]可交债!A20))=6,TRIM([2]可交债!A20)&".SZ",TRIM([2]可交债!A20)) -> 137192.SH | C20: =IFERROR(VLOOKUP(LEFT($B20,6)&"*",[2]可交债!$A:$H,2,FALSE),"") -> 24蜀道EB | D20: =IFERROR(VLOOKUP(LEFT($B20,6)&"*",[2]可交债!$A:$H,3,FALSE),"") -> 600039.SH | E20: =IFERROR(VLOOKUP(LEFT($B20,6)&"*",[2]可交债!$A:$H,4,FALSE),"") -> 四川路桥 | F20: =SUMPRODUCT((LEFT(TRIM('[3]现券交易信息（逐笔）'!$B$2:$B$500),6)=LEFT($B20,6))*(IFERROR(--SUBSTITUTE('[3]现券交易信息（逐笔）'!$G$2:$G$500,",",""),0)))+SUMIF([1]sheet1!$D$2:$D$500,LEFT($B20,6)&"*",[1]sheet1!$M$2:$M$500) -> 0 | G20: =SUMPRODUCT((LEFT(TRIM('[3]现券交易信息（逐笔）'!$B$2:$B$500),6)=LEFT($B20,6))*(IFERROR(--SUBSTITUTE('[3]现券交易信息（逐笔）'!$F$2:$F$500,",",""),0)*100))+SUMIF([1]sheet1!$D$2:$D$500,LEFT($B20,6)&"*",[1]sheet1!$L$2:$L$500)*100 -> 0 | H20: =IF(G20=0,"",ROUND(F20*10000/G20,4)) | I20: =IFERROR(VLOOKUP(LEFT($B20,6)&"*",[2]可交债!$A:$H,5,FALSE),"") -> 0.01 | J20: =IFERROR(VLOOKUP(LEFT($B20,6)&"*",[2]可交债!$A:$H,6,FALSE),"") -> 3 | K20: =IFERROR(VLOOKUP(LEFT($B20,6)&"*",[2]可交债!$A:$H,7,FALSE),"") -> 7.88 | L20: =IFERROR(VLOOKUP(LEFT($B20,6)&"*",[2]可交债!$A:$H,8,FALSE),"") -> 8.47 | M20: =IFERROR(VLOOKUP(LEFT($B20,6),[4]中证可交换债券估值!$A:$H,5,FALSE),"") -> 120.5041 | N20: =IFERROR(VLOOKUP(LEFT($B20,6),[4]中证可交换债券估值!$A:$H,6,FALSE),"") -> 19.7355 | O20: =IFERROR(VLOOKUP(LEFT($B20,6),[4]中证可交换债券估值!$A:$H,7,FALSE),"") -> 100.7686
A21: =TEXT([1]sheet1!B2,"yyyy-mm-dd") -> 2026-08-17 | B21: =IF(LEN(TRIM([1]sheet1!D2))=6,TRIM([1]sheet1!D2)&".SZ",TRIM([1]sheet1!D2)) -> 137188.SH | C21: =IFERROR(VLOOKUP(LEFT($B21,6)&"*",[2]可交债!$A:$H,2,FALSE),"") -> 24穗港EB | D21: =IFERROR(VLOOKUP(LEFT($B21,6)&"*",[2]可交债!$A:$H,3,FALSE),"") -> 601228.SH | E21: =IFERROR(VLOOKUP(LEFT($B21,6)&"*",[2]可交债!$A:$H,4,FALSE),"") -> 广州港 | F21: =[1]sheet1!M2 -> 330.15 | G21: =[1]sheet1!L2*100 -> 30000 | H21: =IF(G21=0,"",ROUND(F21*10000/G21,4)) -> 110.05 | I21: =IFERROR(VLOOKUP(LEFT($B21,6)&"*",[2]可交债!$A:$H,5,FALSE),"") -> 0.1 | J21: =IFERROR(VLOOKUP(LEFT($B21,6)&"*",[2]可交债!$A:$H,6,FALSE),"") -> 5 | K21: =IFERROR(VLOOKUP(LEFT($B21,6)&"*",[2]可交债!$A:$H,7,FALSE),"") -> 3.63 | L21: =IFERROR(VLOOKUP(LEFT($B21,6)&"*",[2]可交债!$A:$H,8,FALSE),"") -> 3.04 | M21: =IFERROR(VLOOKUP(LEFT($B21,6),[4]中证可交换债券估值!$A:$H,5,FALSE),"") -> 106.3063 | N21: =IFERROR(VLOOKUP(LEFT($B21,6),[4]中证可交换债券估值!$A:$H,6,FALSE),"") -> 3.0021 | O21: =IFERROR(VLOOKUP(LEFT($B21,6),[4]中证可交换债券估值!$A:$H,7,FALSE),"") -> 103.3042
A22: =TEXT([1]sheet1!B3,"yyyy-mm-dd") -> 2026-08-17 | B22: =IF(LEN(TRIM([1]sheet1!D3))=6,TRIM([1]sheet1!D3)&".SZ",TRIM([1]sheet1!D3)) -> 137188.SH | C22: =IFERROR(VLOOKUP(LEFT($B22,6)&"*",[2]可交债!$A:$H,2,FALSE),"") -> 24穗港EB | D22: =IFERROR(VLOOKUP(LEFT($B22,6)&"*",[2]可交债!$A:$H,3,FALSE),"") -> 601228.SH | E22: =IFERROR(VLOOKUP(LEFT($B22,6)&"*",[2]可交债!$A:$H,4,FALSE),"") -> 广州港 | F22: =[1]sheet1!M3 -> 330 | G22: =[1]sheet1!L3*100 -> 30000 | H22: =IF(G22=0,"",ROUND(F22*10000/G22,4)) -> 110 | I22: =IFERROR(VLOOKUP(LEFT($B22,6)&"*",[2]可交债!$A:$H,5,FALSE),"") -> 0.1 | J22: =IFERROR(VLOOKUP(LEFT($B22,6)&"*",[2]可交债!$A:$H,6,FALSE),"") -> 5 | K22: =IFERROR(VLOOKUP(LEFT($B22,6)&"*",[2]可交债!$A:$H,7,FALSE),"") -> 3.63 | L22: =IFERROR(VLOOKUP(LEFT($B22,6)&"*",[2]可交债!$A:$H,8,FALSE),"") -> 3.04 | M22: =IFERROR(VLOOKUP(LEFT($B22,6),[4]中证可交换债券估值!$A:$H,5,FALSE),"") -> 106.3063 | N22: =IFERROR(VLOOKUP(LEFT($B22,6),[4]中证可交换债券估值!$A:$H,6,FALSE),"") -> 3.0021 | O22: =IFERROR(VLOOKUP(LEFT($B22,6),[4]中证可交换债券估值!$A:$H,7,FALSE),"") -> 103.3042
A23: =TEXT([1]sheet1!$B$3,"yyyy-mm-dd") -> 2026-08-17 | B23: =IF(LEN(TRIM([2]可交债!A22))=6,TRIM([2]可交债!A22)&".SZ",TRIM([2]可交债!A22)) -> 117242.SZ | C23: =IFERROR(VLOOKUP(LEFT($B23,6)&"*",[2]可交债!$A:$H,2,FALSE),"") -> 25成大E1 | D23: =IFERROR(VLOOKUP(LEFT($B23,6)&"*",[2]可交债!$A:$H,3,FALSE),"") -> 000776.SZ | E23: =IFERROR(VLOOKUP(LEFT($B23,6)&"*",[2]可交债!$A:$H,4,FALSE),"") -> 广发证券 | F23: =SUMPRODUCT((LEFT(TRIM('[3]现券交易信息（逐笔）'!$B$2:$B$500),6)=LEFT($B23,6))*(IFERROR(--SUBSTITUTE('[3]现券交易信息（逐笔）'!$G$2:$G$500,",",""),0)))+SUMIF([1]sheet1!$D$2:$D$500,LEFT($B23,6)&"*",[1]sheet1!$M$2:$M$500) -> 0 | G23: =SUMPRODUCT((LEFT(TRIM('[3]现券交易信息（逐笔）'!$B$2:$B$500),6)=LEFT($B23,6))*(IFERROR(--SUBSTITUTE('[3]现券交易信息（逐笔）'!$F$2:$F$500,",",""),0)*100))+SUMIF([1]sheet1!$D$2:$D$500,LEFT($B23,6)&"*",[1]sheet1!$L$2:$L$500)*100 -> 0 | H23: =IF(G23=0,"",ROUND(F23*10000/G23,4)) | I23: =IFERROR(VLOOKUP(LEFT($B23,6)&"*",[2]可交债!$A:$H,5,FALSE),"") -> 0.01 | J23: =IFERROR(VLOOKUP(LEFT($B23,6)&"*",[2]可交债!$A:$H,6,FALSE),"") -> 6 | K23: =IFERROR(VLOOKUP(LEFT($B23,6)&"*",[2]可交债!$A:$H,7,FALSE),"") -> 24.08 | L23: =IFERROR(VLOOKUP(LEFT($B23,6)&"*",[2]可交债!$A:$H,8,FALSE),"") -> 21.21 | M23: =IFERROR(VLOOKUP(LEFT($B23,6),[4]中证可交换债券估值!$A:$H,5,FALSE),"") -> 112.7914 | N23: =IFERROR(VLOOKUP(LEFT($B23,6),[4]中证可交换债券估值!$A:$H,6,FALSE),"") -> 11.0699 | O23: =IFERROR(VLOOKUP(LEFT($B23,6),[4]中证可交换债券估值!$A:$H,7,FALSE),"") -> 101.7215
A24: =TEXT([1]sheet1!$B$3,"yyyy-mm-dd") -> 2026-08-17 | B24: =IF(LEN(TRIM([2]可交债!A23))=6,TRIM([2]可交债!A23)&".SZ",TRIM([2]可交债!A23)) -> 117247.SZ | C24: =IFERROR(VLOOKUP(LEFT($B24,6)&"*",[2]可交债!$A:$H,2,FALSE),"") -> 25成大E2 | D24: =IFERROR(VLOOKUP(LEFT($B24,6)&"*",[2]可交债!$A:$H,3,FALSE),"") -> 000776.SZ | E24: =IFERROR(VLOOKUP(LEFT($B24,6)&"*",[2]可交债!$A:$H,4,FALSE),"") -> 广发证券 | F24: =SUMPRODUCT((LEFT(TRIM('[3]现券交易信息（逐笔）'!$B$2:$B$500),6)=LEFT($B24,6))*(IFERROR(--SUBSTITUTE('[3]现券交易信息（逐笔）'!$G$2:$G$500,",",""),0)))+SUMIF([1]sheet1!$D$2:$D$500,LEFT($B24,6)&"*",[1]sheet1!$M$2:$M$500) -> 0 | G24: =SUMPRODUCT((LEFT(TRIM('[3]现券交易信息（逐笔）'!$B$2:$B$500),6)=LEFT($B24,6))*(IFERROR(--SUBSTITUTE('[3]现券交易信息（逐笔）'!$F$2:$F$500,",",""),0)*100))+SUMIF([1]sheet1!$D$2:$D$500,LEFT($B24,6)&"*",[1]sheet1!$L$2:$L$500)*100 -> 0 | H24: =IF(G24=0,"",ROUND(F24*10000/G24,4)) | I24: =IFERROR(VLOOKUP(LEFT($B24,6)&"*",[2]可交债!$A:$H,5,FALSE),"") -> 0.01 | J24: =IFERROR(VLOOKUP(LEFT($B24,6)&"*",[2]可交债!$A:$H,6,FALSE),"") -> 6 | K24: =IFERROR(VLOOKUP(LEFT($B24,6)&"*",[2]可交债!$A:$H,7,FALSE),"") -> 24.08 | L24: =IFERROR(VLOOKUP(LEFT($B24,6)&"*",[2]可交债!$A:$H,8,FALSE),"") -> 21.21 | M24: =IFERROR(VLOOKUP(LEFT($B24,6),[4]中证可交换债券估值!$A:$H,5,FALSE),"") -> 115.457 | N24: =IFERROR(VLOOKUP(LEFT($B24,6),[4]中证可交换债券估值!$A:$H,6,FALSE),"") -> 14.2288 | O24: =IFERROR(VLOOKUP(LEFT($B24,6),[4]中证可交换债券估值!$A:$H,7,FALSE),"") -> 101.2282
A25: =TEXT([1]sheet1!$B$3,"yyyy-mm-dd") -> 2026-08-17 | B25: =IF(LEN(TRIM([2]可交债!A24))=6,TRIM([2]可交债!A24)&".SZ",TRIM([2]可交债!A24)) -> 117231.SZ | C25: =IFERROR(VLOOKUP(LEFT($B25,6)&"*",[2]可交债!$A:$H,2,FALSE),"") -> 25华强E1 | D25: =IFERROR(VLOOKUP(LEFT($B25,6)&"*",[2]可交债!$A:$H,3,FALSE),"") -> 000062.SZ | E25: =IFERROR(VLOOKUP(LEFT($B25,6)&"*",[2]可交债!$A:$H,4,FALSE),"") -> 深圳华强 | F25: =SUMPRODUCT((LEFT(TRIM('[3]现券交易信息（逐笔）'!$B$2:$B$500),6)=LEFT($B25,6))*(IFERROR(--SUBSTITUTE('[3]现券交易信息（逐笔）'!$G$2:$G$500,",",""),0)))+SUMIF([1]sheet1!$D$2:$D$500,LEFT($B25,6)&"*",[1]sheet1!$M$2:$M$500) -> 0 | G25: =SUMPRODUCT((LEFT(TRIM('[3]现券交易信息（逐笔）'!$B$2:$B$500),6)=LEFT($B25,6))*(IFERROR(--SUBSTITUTE('[3]现券交易信息（逐笔）'!$F$2:$F$500,",",""),0)*100))+SUMIF([1]sheet1!$D$2:$D$500,LEFT($B25,6)&"*",[1]sheet1!$L$2:$L$500)*100 -> 0 | H25: =IF(G25=0,"",ROUND(F25*10000/G25,4)) | I25: =IFERROR(VLOOKUP(LEFT($B25,6)&"*",[2]可交债!$A:$H,5,FALSE),"") -> 0.01 | J25: =IFERROR(VLOOKUP(LEFT($B25,6)&"*",[2]可交债!$A:$H,6,FALSE),"") -> 6 | K25: =IFERROR(VLOOKUP(LEFT($B25,6)&"*",[2]可交债!$A:$H,7,FALSE),"") -> 29.87 | L25: =IFERROR(VLOOKUP(LEFT($B25,6)&"*",[2]可交债!$A:$H,8,FALSE),"") -> 23.74 | M25: =IFERROR(VLOOKUP(LEFT($B25,6),[4]中证可交换债券估值!$A:$H,5,FALSE),"") -> 110.8618 | N25: =IFERROR(VLOOKUP(LEFT($B25,6),[4]中证可交换债券估值!$A:$H,6,FALSE),"") -> 8.9298 | O25: =IFERROR(VLOOKUP(LEFT($B25,6),[4]中证可交换债券估值!$A:$H,7,FALSE),"") -> 101.932
A26: =TEXT([1]sheet1!$B$3,"yyyy-mm-dd") -> 2026-08-17 | B26: =IF(LEN(TRIM([2]可交债!A25))=6,TRIM([2]可交债!A25)&".SZ",TRIM([2]可交债!A25)) -> 117232.SZ | C26: =IFERROR(VLOOKUP(LEFT($B26,6)&"*",[2]可交债!$A:$H,2,FALSE),"") -> 25华强E2 | D26: =IFERROR(VLOOKUP(LEFT($B26,6)&"*",[2]可交债!$A:$H,3,FALSE),"") -> 000062.SZ | E26: =IFERROR(VLOOKUP(LEFT($B26,6)&"*",[2]可交债!$A:$H,4,FALSE),"") -> 深圳华强 | F26: =SUMPRODUCT((LEFT(TRIM('[3]现券交易信息（逐笔）'!$B$2:$B$500),6)=LEFT($B26,6))*(IFERROR(--SUBSTITUTE('[3]现券交易信息（逐笔）'!$G$2:$G$500,",",""),0)))+SUMIF([1]sheet1!$D$2:$D$500,LEFT($B26,6)&"*",[1]sheet1!$M$2:$M$500) -> 0 | G26: =SUMPRODUCT((LEFT(TRIM('[3]现券交易信息（逐笔）'!$B$2:$B$500),6)=LEFT($B26,6))*(IFERROR(--SUBSTITUTE('[3]现券交易信息（逐笔）'!$F$2:$F$500,",",""),0)*100))+SUMIF([1]sheet1!$D$2:$D$500,LEFT($B26,6)&"*",[1]sheet1!$L$2:$L$500)*100 -> 0 | H26: =IF(G26=0,"",ROUND(F26*10000/G26,4)) | I26: =IFERROR(VLOOKUP(LEFT($B26,6)&"*",[2]可交债!$A:$H,5,FALSE),"") -> 0.01 | J26: =IFERROR(VLOOKUP(LEFT($B26,6)&"*",[2]可交债!$A:$H,6,FALSE),"") -> 6 | K26: =IFERROR(VLOOKUP(LEFT($B26,6)&"*",[2]可交债!$A:$H,7,FALSE),"") -> 29.87 | L26: =IFERROR(VLOOKUP(LEFT($B26,6)&"*",[2]可交债!$A:$H,8,FALSE),"") -> 23.74 | M26: =IFERROR(VLOOKUP(LEFT($B26,6),[4]中证可交换债券估值!$A:$H,5,FALSE),"") -> 107.9655 | N26: =IFERROR(VLOOKUP(LEFT($B26,6),[4]中证可交换债券估值!$A:$H,6,FALSE),"") -> 6.0776 | O26: =IFERROR(VLOOKUP(LEFT($B26,6),[4]中证可交换债券估值!$A:$H,7,FALSE),"") -> 101.8879
A27: =TEXT([1]sheet1!$B$3,"yyyy-mm-dd") -> 2026-08-17 | B27: =IF(LEN(TRIM([2]可交债!A26))=6,TRIM([2]可交债!A26)&".SZ",TRIM([2]可交债!A26)) -> 117245.SZ | C27: =IFERROR(VLOOKUP(LEFT($B27,6)&"*",[2]可交债!$A:$H,2,FALSE),"") -> 25华强E3 | D27: =IFERROR(VLOOKUP(LEFT($B27,6)&"*",[2]可交债!$A:$H,3,FALSE),"") -> 000062.SZ | E27: =IFERROR(VLOOKUP(LEFT($B27,6)&"*",[2]可交债!$A:$H,4,FALSE),"") -> 深圳华强 | F27: =SUMPRODUCT((LEFT(TRIM('[3]现券交易信息（逐笔）'!$B$2:$B$500),6)=LEFT($B27,6))*(IFERROR(--SUBSTITUTE('[3]现券交易信息（逐笔）'!$G$2:$G$500,",",""),0)))+SUMIF([1]sheet1!$D$2:$D$500,LEFT($B27,6)&"*",[1]sheet1!$M$2:$M$500) -> 0 | G27: =SUMPRODUCT((LEFT(TRIM('[3]现券交易信息（逐笔）'!$B$2:$B$500),6)=LEFT($B27,6))*(IFERROR(--SUBSTITUTE('[3]现券交易信息（逐笔）'!$F$2:$F$500,",",""),0)*100))+SUMIF([1]sheet1!$D$2:$D$500,LEFT($B27,6)&"*",[1]sheet1!$L$2:$L$500)*100 -> 0 | H27: =IF(G27=0,"",ROUND(F27*10000/G27,4)) | I27: =IFERROR(VLOOKUP(LEFT($B27,6)&"*",[2]可交债!$A:$H,5,FALSE),"") -> 0.01 | J27: =IFERROR(VLOOKUP(LEFT($B27,6)&"*",[2]可交债!$A:$H,6,FALSE),"") -> 3 | K27: =IFERROR(VLOOKUP(LEFT($B27,6)&"*",[2]可交债!$A:$H,7,FALSE),"") -> 29.87 | L27: =IFERROR(VLOOKUP(LEFT($B27,6)&"*",[2]可交债!$A:$H,8,FALSE),"") -> 23.74 | M27: =IFERROR(VLOOKUP(LEFT($B27,6),[4]中证可交换债券估值!$A:$H,5,FALSE),"") -> 107.4791 | N27: =IFERROR(VLOOKUP(LEFT($B27,6),[4]中证可交换债券估值!$A:$H,6,FALSE),"") -> 9.8037 | O27: =IFERROR(VLOOKUP(LEFT($B27,6),[4]中证可交换债券估值!$A:$H,7,FALSE),"") -> 97.6754
A28: =TEXT([1]sheet1!$B$3,"yyyy-mm-dd") -> 2026-08-17 | B28: =IF(LEN(TRIM([2]可交债!A27))=6,TRIM([2]可交债!A27)&".SZ",TRIM([2]可交债!A27)) -> 117238.SZ | C28: =IFERROR(VLOOKUP(LEFT($B28,6)&"*",[2]可交债!$A:$H,2,FALSE),"") -> 25霍煤EB | D28: =IFERROR(VLOOKUP(LEFT($B28,6)&"*",[2]可交债!$A:$H,3,FALSE),"") -> 002128.SZ | E28: =IFERROR(VLOOKUP(LEFT($B28,6)&"*",[2]可交债!$A:$H,4,FALSE),"") -> 电投能源 | F28: =SUMPRODUCT((LEFT(TRIM('[3]现券交易信息（逐笔）'!$B$2:$B$500),6)=LEFT($B28,6))*(IFERROR(--SUBSTITUTE('[3]现券交易信息（逐笔）'!$G$2:$G$500,",",""),0)))+SUMIF([1]sheet1!$D$2:$D$500,LEFT($B28,6)&"*",[1]sheet1!$M$2:$M$500) -> 0 | G28: =SUMPRODUCT((LEFT(TRIM('[3]现券交易信息（逐笔）'!$B$2:$B$500),6)=LEFT($B28,6))*(IFERROR(--SUBSTITUTE('[3]现券交易信息（逐笔）'!$F$2:$F$500,",",""),0)*100))+SUMIF([1]sheet1!$D$2:$D$500,LEFT($B28,6)&"*",[1]sheet1!$L$2:$L$500)*100 -> 0 | H28: =IF(G28=0,"",ROUND(F28*10000/G28,4)) | I28: =IFERROR(VLOOKUP(LEFT($B28,6)&"*",[2]可交债!$A:$H,5,FALSE),"") -> 0.5 | J28: =IFERROR(VLOOKUP(LEFT($B28,6)&"*",[2]可交债!$A:$H,6,FALSE),"") -> 15 | K28: =IFERROR(VLOOKUP(LEFT($B28,6)&"*",[2]可交债!$A:$H,7,FALSE),"") -> 53.7 | L28: =IFERROR(VLOOKUP(LEFT($B28,6)&"*",[2]可交债!$A:$H,8,FALSE),"") -> 27.26 | M28: =IFERROR(VLOOKUP(LEFT($B28,6),[4]中证可交换债券估值!$A:$H,5,FALSE),"") -> 108.4058 | N28: =IFERROR(VLOOKUP(LEFT($B28,6),[4]中证可交换债券估值!$A:$H,6,FALSE),"") -> 1.0715 | O28: =IFERROR(VLOOKUP(LEFT($B28,6),[4]中证可交换债券估值!$A:$H,7,FALSE),"") -> 107.3343
A29: =TEXT([1]sheet1!$B$3,"yyyy-mm-dd") -> 2026-08-17 | B29: =IF(LEN(TRIM([2]可交债!A28))=6,TRIM([2]可交债!A28)&".SZ",TRIM([2]可交债!A28)) -> 137195.SH | C29: =IFERROR(VLOOKUP(LEFT($B29,6)&"*",[2]可交债!$A:$H,2,FALSE),"") -> 25康01EB | D29: =IFERROR(VLOOKUP(LEFT($B29,6)&"*",[2]可交债!$A:$H,3,FALSE),"") -> 601127.SH | E29: =IFERROR(VLOOKUP(LEFT($B29,6)&"*",[2]可交债!$A:$H,4,FALSE),"") -> 赛力斯 | F29: =SUMPRODUCT((LEFT(TRIM('[3]现券交易信息（逐笔）'!$B$2:$B$500),6)=LEFT($B29,6))*(IFERROR(--SUBSTITUTE('[3]现券交易信息（逐笔）'!$G$2:$G$500,",",""),0)))+SUMIF([1]sheet1!$D$2:$D$500,LEFT($B29,6)&"*",[1]sheet1!$M$2:$M$500) -> 0 | G29: =SUMPRODUCT((LEFT(TRIM('[3]现券交易信息（逐笔）'!$B$2:$B$500),6)=LEFT($B29,6))*(IFERROR(--SUBSTITUTE('[3]现券交易信息（逐笔）'!$F$2:$F$500,",",""),0)*100))+SUMIF([1]sheet1!$D$2:$D$500,LEFT($B29,6)&"*",[1]sheet1!$L$2:$L$500)*100 -> 0 | H29: =IF(G29=0,"",ROUND(F29*10000/G29,4)) | I29: =IFERROR(VLOOKUP(LEFT($B29,6)&"*",[2]可交债!$A:$H,5,FALSE),"") -> 0.1 | J29: =IFERROR(VLOOKUP(LEFT($B29,6)&"*",[2]可交债!$A:$H,6,FALSE),"") -> 9 | K29: =IFERROR(VLOOKUP(LEFT($B29,6)&"*",[2]可交债!$A:$H,7,FALSE),"") -> 121.2 | L29: =IFERROR(VLOOKUP(LEFT($B29,6)&"*",[2]可交债!$A:$H,8,FALSE),"") -> 53.14 | M29: =IFERROR(VLOOKUP(LEFT($B29,6),[4]中证可交换债券估值!$A:$H,5,FALSE),"") -> 103.8712 | N29: =IFERROR(VLOOKUP(LEFT($B29,6),[4]中证可交换债券估值!$A:$H,6,FALSE),"") -> 0.6447 | O29: =IFERROR(VLOOKUP(LEFT($B29,6),[4]中证可交换债券估值!$A:$H,7,FALSE),"") -> 103.2265
A30: =TEXT([1]sheet1!$B$3,"yyyy-mm-dd") -> 2026-08-17 | B30: =IF(LEN(TRIM([2]可交债!A29))=6,TRIM([2]可交债!A29)&".SZ",TRIM([2]可交债!A29)) -> 137196.SH | C30: =IFERROR(VLOOKUP(LEFT($B30,6)&"*",[2]可交债!$A:$H,2,FALSE),"") -> 25康02EB | D30: =IFERROR(VLOOKUP(LEFT($B30,6)&"*",[2]可交债!$A:$H,3,FALSE),"") -> 601127.SH | E30: =IFERROR(VLOOKUP(LEFT($B30,6)&"*",[2]可交债!$A:$H,4,FALSE),"") -> 赛力斯 | F30: =SUMPRODUCT((LEFT(TRIM('[3]现券交易信息（逐笔）'!$B$2:$B$500),6)=LEFT($B30,6))*(IFERROR(--SUBSTITUTE('[3]现券交易信息（逐笔）'!$G$2:$G$500,",",""),0)))+SUMIF([1]sheet1!$D$2:$D$500,LEFT($B30,6)&"*",[1]sheet1!$M$2:$M$500) -> 0 | G30: =SUMPRODUCT((LEFT(TRIM('[3]现券交易信息（逐笔）'!$B$2:$B$500),6)=LEFT($B30,6))*(IFERROR(--SUBSTITUTE('[3]现券交易信息（逐笔）'!$F$2:$F$500,",",""),0)*100))+SUMIF([1]sheet1!$D$2:$D$500,LEFT($B30,6)&"*",[1]sheet1!$L$2:$L$500)*100 -> 0 | H30: =IF(G30=0,"",ROUND(F30*10000/G30,4)) | I30: =IFERROR(VLOOKUP(LEFT($B30,6)&"*",[2]可交债!$A:$H,5,FALSE),"") -> 0.1 | J30: =IFERROR(VLOOKUP(LEFT($B30,6)&"*",[2]可交债!$A:$H,6,FALSE),"") -> 9 | K30: =IFERROR(VLOOKUP(LEFT($B30,6)&"*",[2]可交债!$A:$H,7,FALSE),"") -> 121.2 | L30: =IFERROR(VLOOKUP(LEFT($B30,6)&"*",[2]可交债!$A:$H,8,FALSE),"") -> 53.14 | M30: =IFERROR(VLOOKUP(LEFT($B30,6),[4]中证可交换债券估值!$A:$H,5,FALSE),"") -> 103.8629 | N30: =IFERROR(VLOOKUP(LEFT($B30,6),[4]中证可交换债券估值!$A:$H,6,FALSE),"") -> 0.6364 | O30: =IFERROR(VLOOKUP(LEFT($B30,6),[4]中证可交换债券估值!$A:$H,7,FALSE),"") -> 103.2265
A31: =TEXT([1]sheet1!$B$3,"yyyy-mm-dd") -> 2026-08-17 | B31: =IF(LEN(TRIM([2]可交债!A30))=6,TRIM([2]可交债!A30)&".SZ",TRIM([2]可交债!A30)) -> 117246.SZ | C31: =IFERROR(VLOOKUP(LEFT($B31,6)&"*",[2]可交债!$A:$H,2,FALSE),"") -> 25盛虹EB | D31: =IFERROR(VLOOKUP(LEFT($B31,6)&"*",[2]可交债!$A:$H,3,FALSE),"") -> 000301.SZ | E31: =IFERROR(VLOOKUP(LEFT($B31,6)&"*",[2]可交债!$A:$H,4,FALSE),"") -> 东方盛虹 | F31: =SUMPRODUCT((LEFT(TRIM('[3]现券交易信息（逐笔）'!$B$2:$B$500),6)=LEFT($B31,6))*(IFERROR(--SUBSTITUTE('[3]现券交易信息（逐笔）'!$G$2:$G$500,",",""),0)))+SUMIF([1]sheet1!$D$2:$D$500,LEFT($B31,6)&"*",[1]sheet1!$M$2:$M$500) -> 0 | G31: =SUMPRODUCT((LEFT(TRIM('[3]现券交易信息（逐笔）'!$B$2:$B$500),6)=LEFT($B31,6))*(IFERROR(--SUBSTITUTE('[3]现券交易信息（逐笔）'!$F$2:$F$500,",",""),0)*100))+SUMIF([1]sheet1!$D$2:$D$500,LEFT($B31,6)&"*",[1]sheet1!$L$2:$L$500)*100 -> 0 | H31: =IF(G31=0,"",ROUND(F31*10000/G31,4)) | I31: =IFERROR(VLOOKUP(LEFT($B31,6)&"*",[2]可交债!$A:$H,5,FALSE),"") -> 0.1 | J31: =IFERROR(VLOOKUP(LEFT($B31,6)&"*",[2]可交债!$A:$H,6,FALSE),"") -> 5 | K31: =IFERROR(VLOOKUP(LEFT($B31,6)&"*",[2]可交债!$A:$H,7,FALSE),"") -> 12.5 | L31: =IFERROR(VLOOKUP(LEFT($B31,6)&"*",[2]可交债!$A:$H,8,FALSE),"") -> 12.66 | M31: =IFERROR(VLOOKUP(LEFT($B31,6),[4]中证可交换债券估值!$A:$H,5,FALSE),"") -> 111.4862 | N31: =IFERROR(VLOOKUP(LEFT($B31,6),[4]中证可交换债券估值!$A:$H,6,FALSE),"") -> 10.5465 | O31: =IFERROR(VLOOKUP(LEFT($B31,6),[4]中证可交换债券估值!$A:$H,7,FALSE),"") -> 100.9397
A32: =TEXT([1]sheet1!B4,"yyyy-mm-dd") -> 2026-08-17 | B32: =IF(LEN(TRIM([1]sheet1!D4))=6,TRIM([1]sheet1!D4)&".SZ",TRIM([1]sheet1!D4)) -> 137194.SH | C32: =IFERROR(VLOOKUP(LEFT($B32,6)&"*",[2]可交债!$A:$H,2,FALSE),"") -> 25蜀道EB | D32: =IFERROR(VLOOKUP(LEFT($B32,6)&"*",[2]可交债!$A:$H,3,FALSE),"") -> 600039.SH | E32: =IFERROR(VLOOKUP(LEFT($B32,6)&"*",[2]可交债!$A:$H,4,FALSE),"") -> 四川路桥 | F32: =[1]sheet1!M4 -> 1120 | G32: =[1]sheet1!L4*100 -> 100000 | H32: =IF(G32=0,"",ROUND(F32*10000/G32,4)) -> 112 | I32: =IFERROR(VLOOKUP(LEFT($B32,6)&"*",[2]可交债!$A:$H,5,FALSE),"") -> 0.01 | J32: =IFERROR(VLOOKUP(LEFT($B32,6)&"*",[2]可交债!$A:$H,6,FALSE),"") -> 3 | K32: =IFERROR(VLOOKUP(LEFT($B32,6)&"*",[2]可交债!$A:$H,7,FALSE),"") -> 8.13 | L32: =IFERROR(VLOOKUP(LEFT($B32,6)&"*",[2]可交债!$A:$H,8,FALSE),"") -> 8.47 | M32: =IFERROR(VLOOKUP(LEFT($B32,6),[4]中证可交换债券估值!$A:$H,5,FALSE),"") -> 111.357 | N32: =IFERROR(VLOOKUP(LEFT($B32,6),[4]中证可交换债券估值!$A:$H,6,FALSE),"") -> 11.1127 | O32: =IFERROR(VLOOKUP(LEFT($B32,6),[4]中证可交换债券估值!$A:$H,7,FALSE),"") -> 100.2443
A33: =TEXT([1]sheet1!B5,"yyyy-mm-dd") -> 2026-08-17 | B33: =IF(LEN(TRIM([1]sheet1!D5))=6,TRIM([1]sheet1!D5)&".SZ",TRIM([1]sheet1!D5)) -> 137194.SH | C33: =IFERROR(VLOOKUP(LEFT($B33,6)&"*",[2]可交债!$A:$H,2,FALSE),"") -> 25蜀道EB | D33: =IFERROR(VLOOKUP(LEFT($B33,6)&"*",[2]可交债!$A:$H,3,FALSE),"") -> 600039.SH | E33: =IFERROR(VLOOKUP(LEFT($B33,6)&"*",[2]可交债!$A:$H,4,FALSE),"") -> 四川路桥 | F33: =[1]sheet1!M5 -> 336.15 | G33: =[1]sheet1!L5*100 -> 30000 | H33: =IF(G33=0,"",ROUND(F33*10000/G33,4)) -> 112.05 | I33: =IFERROR(VLOOKUP(LEFT($B33,6)&"*",[2]可交债!$A:$H,5,FALSE),"") -> 0.01 | J33: =IFERROR(VLOOKUP(LEFT($B33,6)&"*",[2]可交债!$A:$H,6,FALSE),"") -> 3 | K33: =IFERROR(VLOOKUP(LEFT($B33,6)&"*",[2]可交债!$A:$H,7,FALSE),"") -> 8.13 | L33: =IFERROR(VLOOKUP(LEFT($B33,6)&"*",[2]可交债!$A:$H,8,FALSE),"") -> 8.47 | M33: =IFERROR(VLOOKUP(LEFT($B33,6),[4]中证可交换债券估值!$A:$H,5,FALSE),"") -> 111.357 | N33: =IFERROR(VLOOKUP(LEFT($B33,6),[4]中证可交换债券估值!$A:$H,6,FALSE),"") -> 11.1127 | O33: =IFERROR(VLOOKUP(LEFT($B33,6),[4]中证可交换债券估值!$A:$H,7,FALSE),"") -> 100.2443
A34: =TEXT([1]sheet1!B6,"yyyy-mm-dd") -> 2026-08-17 | B34: =IF(LEN(TRIM([1]sheet1!D6))=6,TRIM([1]sheet1!D6)&".SZ",TRIM([1]sheet1!D6)) -> 137194.SH | C34: =IFERROR(VLOOKUP(LEFT($B34,6)&"*",[2]可交债!$A:$H,2,FALSE),"") -> 25蜀道EB | D34: =IFERROR(VLOOKUP(LEFT($B34,6)&"*",[2]可交债!$A:$H,3,FALSE),"") -> 600039.SH | E34: =IFERROR(VLOOKUP(LEFT($B34,6)&"*",[2]可交债!$A:$H,4,FALSE),"") -> 四川路桥 | F34: =[1]sheet1!M6 -> 336.15 | G34: =[1]sheet1!L6*100 -> 30000 | H34: =IF(G34=0,"",ROUND(F34*10000/G34,4)) -> 112.05 | I34: =IFERROR(VLOOKUP(LEFT($B34,6)&"*",[2]可交债!$A:$H,5,FALSE),"") -> 0.01 | J34: =IFERROR(VLOOKUP(LEFT($B34,6)&"*",[2]可交债!$A:$H,6,FALSE),"") -> 3 | K34: =IFERROR(VLOOKUP(LEFT($B34,6)&"*",[2]可交债!$A:$H,7,FALSE),"") -> 8.13 | L34: =IFERROR(VLOOKUP(LEFT($B34,6)&"*",[2]可交债!$A:$H,8,FALSE),"") -> 8.47 | M34: =IFERROR(VLOOKUP(LEFT($B34,6),[4]中证可交换债券估值!$A:$H,5,FALSE),"") -> 111.357 | N34: =IFERROR(VLOOKUP(LEFT($B34,6),[4]中证可交换债券估值!$A:$H,6,FALSE),"") -> 11.1127 | O34: =IFERROR(VLOOKUP(LEFT($B34,6),[4]中证可交换债券估值!$A:$H,7,FALSE),"") -> 100.2443
A35: =TEXT([1]sheet1!B7,"yyyy-mm-dd") -> 2026-08-17 | B35: =IF(LEN(TRIM([1]sheet1!D7))=6,TRIM([1]sheet1!D7)&".SZ",TRIM([1]sheet1!D7)) -> 137194.SH | C35: =IFERROR(VLOOKUP(LEFT($B35,6)&"*",[2]可交债!$A:$H,2,FALSE),"") -> 25蜀道EB | D35: =IFERROR(VLOOKUP(LEFT($B35,6)&"*",[2]可交债!$A:$H,3,FALSE),"") -> 600039.SH | E35: =IFERROR(VLOOKUP(LEFT($B35,6)&"*",[2]可交债!$A:$H,4,FALSE),"") -> 四川路桥 | F35: =[1]sheet1!M7 -> 448.2 | G35: =[1]sheet1!L7*100 -> 40000 | H35: =IF(G35=0,"",ROUND(F35*10000/G35,4)) -> 112.05 | I35: =IFERROR(VLOOKUP(LEFT($B35,6)&"*",[2]可交债!$A:$H,5,FALSE),"") -> 0.01 | J35: =IFERROR(VLOOKUP(LEFT($B35,6)&"*",[2]可交债!$A:$H,6,FALSE),"") -> 3 | K35: =IFERROR(VLOOKUP(LEFT($B35,6)&"*",[2]可交债!$A:$H,7,FALSE),"") -> 8.13 | L35: =IFERROR(VLOOKUP(LEFT($B35,6)&"*",[2]可交债!$A:$H,8,FALSE),"") -> 8.47 | M35: =IFERROR(VLOOKUP(LEFT($B35,6),[4]中证可交换债券估值!$A:$H,5,FALSE),"") -> 111.357 | N35: =IFERROR(VLOOKUP(LEFT($B35,6),[4]中证可交换债券估值!$A:$H,6,FALSE),"") -> 11.1127 | O35: =IFERROR(VLOOKUP(LEFT($B35,6),[4]中证可交换债券估值!$A:$H,7,FALSE),"") -> 100.2443
A36: =TEXT([1]sheet1!$B$3,"yyyy-mm-dd") -> 2026-08-17 | B36: =IF(LEN(TRIM([2]可交债!A32))=6,TRIM([2]可交债!A32)&".SZ",TRIM([2]可交债!A32)) -> 117236.SZ | C36: =IFERROR(VLOOKUP(LEFT($B36,6)&"*",[2]可交债!$A:$H,2,FALSE),"") -> 25顺控KEB1 | D36: =IFERROR(VLOOKUP(LEFT($B36,6)&"*",[2]可交债!$A:$H,3,FALSE),"") -> 003039.SZ | E36: =IFERROR(VLOOKUP(LEFT($B36,6)&"*",[2]可交债!$A:$H,4,FALSE),"") -> 顺控发展 | F36: =SUMPRODUCT((LEFT(TRIM('[3]现券交易信息（逐笔）'!$B$2:$B$500),6)=LEFT($B36,6))*(IFERROR(--SUBSTITUTE('[3]现券交易信息（逐笔）'!$G$2:$G$500,",",""),0)))+SUMIF([1]sheet1!$D$2:$D$500,LEFT($B36,6)&"*",[1]sheet1!$M$2:$M$500) -> 0 | G36: =SUMPRODUCT((LEFT(TRIM('[3]现券交易信息（逐笔）'!$B$2:$B$500),6)=LEFT($B36,6))*(IFERROR(--SUBSTITUTE('[3]现券交易信息（逐笔）'!$F$2:$F$500,",",""),0)*100))+SUMIF([1]sheet1!$D$2:$D$500,LEFT($B36,6)&"*",[1]sheet1!$L$2:$L$500)*100 -> 0 | H36: =IF(G36=0,"",ROUND(F36*10000/G36,4)) | I36: =IFERROR(VLOOKUP(LEFT($B36,6)&"*",[2]可交债!$A:$H,5,FALSE),"") -> 0.01 | J36: =IFERROR(VLOOKUP(LEFT($B36,6)&"*",[2]可交债!$A:$H,6,FALSE),"") -> 3 | K36: =IFERROR(VLOOKUP(LEFT($B36,6)&"*",[2]可交债!$A:$H,7,FALSE),"") -> 14.57 | L36: =IFERROR(VLOOKUP(LEFT($B36,6)&"*",[2]可交债!$A:$H,8,FALSE),"") -> 11.91 | M36: =IFERROR(VLOOKUP(LEFT($B36,6),[4]中证可交换债券估值!$A:$H,5,FALSE),"") -> 105.1527 | N36: =IFERROR(VLOOKUP(LEFT($B36,6),[4]中证可交换债券估值!$A:$H,6,FALSE),"") -> 5.2343 | O36: =IFERROR(VLOOKUP(LEFT($B36,6),[4]中证可交换债券估值!$A:$H,7,FALSE),"") -> 99.9184
A37: =TEXT([1]sheet1!$B$3,"yyyy-mm-dd") -> 2026-08-17 | B37: =IF(LEN(TRIM([2]可交债!A33))=6,TRIM([2]可交债!A33)&".SZ",TRIM([2]可交债!A33)) -> 117244.SZ | C37: =IFERROR(VLOOKUP(LEFT($B37,6)&"*",[2]可交债!$A:$H,2,FALSE),"") -> 25顺控KEB2 | D37: =IFERROR(VLOOKUP(LEFT($B37,6)&"*",[2]可交债!$A:$H,3,FALSE),"") -> 003039.SZ | E37: =IFERROR(VLOOKUP(LEFT($B37,6)&"*",[2]可交债!$A:$H,4,FALSE),"") -> 顺控发展 | F37: =SUMPRODUCT((LEFT(TRIM('[3]现券交易信息（逐笔）'!$B$2:$B$500),6)=LEFT($B37,6))*(IFERROR(--SUBSTITUTE('[3]现券交易信息（逐笔）'!$G$2:$G$500,",",""),0)))+SUMIF([1]sheet1!$D$2:$D$500,LEFT($B37,6)&"*",[1]sheet1!$M$2:$M$500) -> 0 | G37: =SUMPRODUCT((LEFT(TRIM('[3]现券交易信息（逐笔）'!$B$2:$B$500),6)=LEFT($B37,6))*(IFERROR(--SUBSTITUTE('[3]现券交易信息（逐笔）'!$F$2:$F$500,",",""),0)*100))+SUMIF([1]sheet1!$D$2:$D$500,LEFT($B37,6)&"*",[1]sheet1!$L$2:$L$500)*100 -> 0 | H37: =IF(G37=0,"",ROUND(F37*10000/G37,4)) | I37: =IFERROR(VLOOKUP(LEFT($B37,6)&"*",[2]可交债!$A:$H,5,FALSE),"") -> 0.01 | J37: =IFERROR(VLOOKUP(LEFT($B37,6)&"*",[2]可交债!$A:$H,6,FALSE),"") -> 3 | K37: =IFERROR(VLOOKUP(LEFT($B37,6)&"*",[2]可交债!$A:$H,7,FALSE),"") -> 14.87 | L37: =IFERROR(VLOOKUP(LEFT($B37,6)&"*",[2]可交债!$A:$H,8,FALSE),"") -> 11.91 | M37: =IFERROR(VLOOKUP(LEFT($B37,6),[4]中证可交换债券估值!$A:$H,5,FALSE),"") -> 109.3302 | N37: =IFERROR(VLOOKUP(LEFT($B37,6),[4]中证可交换债券估值!$A:$H,6,FALSE),"") -> 10.0944 | O37: =IFERROR(VLOOKUP(LEFT($B37,6),[4]中证可交换债券估值!$A:$H,7,FALSE),"") -> 99.2358
A38: =TEXT([1]sheet1!$B$3,"yyyy-mm-dd") -> 2026-08-17 | B38: =IF(LEN(TRIM([2]可交债!A34))=6,TRIM([2]可交债!A34)&".SZ",TRIM([2]可交债!A34)) -> 117237.SZ | C38: =IFERROR(VLOOKUP(LEFT($B38,6)&"*",[2]可交债!$A:$H,2,FALSE),"") -> 25万安EB | D38: =IFERROR(VLOOKUP(LEFT($B38,6)&"*",[2]可交债!$A:$H,3,FALSE),"") -> 002590.SZ | E38: =IFERROR(VLOOKUP(LEFT($B38,6)&"*",[2]可交债!$A:$H,4,FALSE),"") -> 万安科技 | F38: =SUMPRODUCT((LEFT(TRIM('[3]现券交易信息（逐笔）'!$B$2:$B$500),6)=LEFT($B38,6))*(IFERROR(--SUBSTITUTE('[3]现券交易信息（逐笔）'!$G$2:$G$500,",",""),0)))+SUMIF([1]sheet1!$D$2:$D$500,LEFT($B38,6)&"*",[1]sheet1!$M$2:$M$500) -> 0 | G38: =SUMPRODUCT((LEFT(TRIM('[3]现券交易信息（逐笔）'!$B$2:$B$500),6)=LEFT($B38,6))*(IFERROR(--SUBSTITUTE('[3]现券交易信息（逐笔）'!$F$2:$F$500,",",""),0)*100))+SUMIF([1]sheet1!$D$2:$D$500,LEFT($B38,6)&"*",[1]sheet1!$L$2:$L$500)*100 -> 0 | H38: =IF(G38=0,"",ROUND(F38*10000/G38,4)) | I38: =IFERROR(VLOOKUP(LEFT($B38,6)&"*",[2]可交债!$A:$H,5,FALSE),"") -> 0.1 | J38: =IFERROR(VLOOKUP(LEFT($B38,6)&"*",[2]可交债!$A:$H,6,FALSE),"") -> 3 | K38: =IFERROR(VLOOKUP(LEFT($B38,6)&"*",[2]可交债!$A:$H,7,FALSE),"") -> 16.72 | L38: =IFERROR(VLOOKUP(LEFT($B38,6)&"*",[2]可交债!$A:$H,8,FALSE),"") -> 9.55 | M38: =IFERROR(VLOOKUP(LEFT($B38,6),[4]中证可交换债券估值!$A:$H,5,FALSE),"") -> 101.5206 | N38: =IFERROR(VLOOKUP(LEFT($B38,6),[4]中证可交换债券估值!$A:$H,6,FALSE),"") -> 2.6149 | O38: =IFERROR(VLOOKUP(LEFT($B38,6),[4]中证可交换债券估值!$A:$H,7,FALSE),"") -> 98.9057
A39: =TEXT([1]sheet1!$B$3,"yyyy-mm-dd") -> 2026-08-17 | B39: =IF(LEN(TRIM([2]可交债!A35))=6,TRIM([2]可交债!A35)&".SZ",TRIM([2]可交债!A35)) -> 117241.SZ | C39: =IFERROR(VLOOKUP(LEFT($B39,6)&"*",[2]可交债!$A:$H,2,FALSE),"") -> 25新华都EB01 | D39: =IFERROR(VLOOKUP(LEFT($B39,6)&"*",[2]可交债!$A:$H,3,FALSE),"") -> 000538.SZ | E39: =IFERROR(VLOOKUP(LEFT($B39,6)&"*",[2]可交债!$A:$H,4,FALSE),"") -> 云南白药 | F39: =SUMPRODUCT((LEFT(TRIM('[3]现券交易信息（逐笔）'!$B$2:$B$500),6)=LEFT($B39,6))*(IFERROR(--SUBSTITUTE('[3]现券交易信息（逐笔）'!$G$2:$G$500,",",""),0)))+SUMIF([1]sheet1!$D$2:$D$500,LEFT($B39,6)&"*",[1]sheet1!$M$2:$M$500) -> 0 | G39: =SUMPRODUCT((LEFT(TRIM('[3]现券交易信息（逐笔）'!$B$2:$B$500),6)=LEFT($B39,6))*(IFERROR(--SUBSTITUTE('[3]现券交易信息（逐笔）'!$F$2:$F$500,",",""),0)*100))+SUMIF([1]sheet1!$D$2:$D$500,LEFT($B39,6)&"*",[1]sheet1!$L$2:$L$500)*100 -> 0 | H39: =IF(G39=0,"",ROUND(F39*10000/G39,4)) | I39: =IFERROR(VLOOKUP(LEFT($B39,6)&"*",[2]可交债!$A:$H,5,FALSE),"") -> 0.1 | J39: =IFERROR(VLOOKUP(LEFT($B39,6)&"*",[2]可交债!$A:$H,6,FALSE),"") -> 6 | K39: =IFERROR(VLOOKUP(LEFT($B39,6)&"*",[2]可交债!$A:$H,7,FALSE),"") -> 70.08 | L39: =IFERROR(VLOOKUP(LEFT($B39,6)&"*",[2]可交债!$A:$H,8,FALSE),"") -> 49.8 | M39: =IFERROR(VLOOKUP(LEFT($B39,6),[4]中证可交换债券估值!$A:$H,5,FALSE),"") -> 104.76 | N39: =IFERROR(VLOOKUP(LEFT($B39,6),[4]中证可交换债券估值!$A:$H,6,FALSE),"") -> 2.3141 | O39: =IFERROR(VLOOKUP(LEFT($B39,6),[4]中证可交换债券估值!$A:$H,7,FALSE),"") -> 102.4459
A40: =TEXT([1]sheet1!$B$3,"yyyy-mm-dd") -> 2026-08-17 | B40: =IF(LEN(TRIM([2]可交债!A36))=6,TRIM([2]可交债!A36)&".SZ",TRIM([2]可交债!A36)) -> 117240.SZ | C40: =IFERROR(VLOOKUP(LEFT($B40,6)&"*",[2]可交债!$A:$H,2,FALSE),"") -> 25粤能源EB | D40: =IFERROR(VLOOKUP(LEFT($B40,6)&"*",[2]可交债!$A:$H,3,FALSE),"") -> 000539.SZ | E40: =IFERROR(VLOOKUP(LEFT($B40,6)&"*",[2]可交债!$A:$H,4,FALSE),"") -> 粤电力A | F40: =SUMPRODUCT((LEFT(TRIM('[3]现券交易信息（逐笔）'!$B$2:$B$500),6)=LEFT($B40,6))*(IFERROR(--SUBSTITUTE('[3]现券交易信息（逐笔）'!$G$2:$G$500,",",""),0)))+SUMIF([1]sheet1!$D$2:$D$500,LEFT($B40,6)&"*",[1]sheet1!$M$2:$M$500) -> 0 | G40: =SUMPRODUCT((LEFT(TRIM('[3]现券交易信息（逐笔）'!$B$2:$B$500),6)=LEFT($B40,6))*(IFERROR(--SUBSTITUTE('[3]现券交易信息（逐笔）'!$F$2:$F$500,",",""),0)*100))+SUMIF([1]sheet1!$D$2:$D$500,LEFT($B40,6)&"*",[1]sheet1!$L$2:$L$500)*100 -> 0 | H40: =IF(G40=0,"",ROUND(F40*10000/G40,4)) | I40: =IFERROR(VLOOKUP(LEFT($B40,6)&"*",[2]可交债!$A:$H,5,FALSE),"") -> 0.01 | J40: =IFERROR(VLOOKUP(LEFT($B40,6)&"*",[2]可交债!$A:$H,6,FALSE),"") -> 1.5 | K40: =IFERROR(VLOOKUP(LEFT($B40,6)&"*",[2]可交债!$A:$H,7,FALSE),"") -> 7.19 | L40: =IFERROR(VLOOKUP(LEFT($B40,6)&"*",[2]可交债!$A:$H,8,FALSE),"") -> 5.64 | M40: =IFERROR(VLOOKUP(LEFT($B40,6),[4]中证可交换债券估值!$A:$H,5,FALSE),"") -> 106.4764 | N40: =IFERROR(VLOOKUP(LEFT($B40,6),[4]中证可交换债券估值!$A:$H,6,FALSE),"") -> 8.3727 | O40: =IFERROR(VLOOKUP(LEFT($B40,6),[4]中证可交换债券估值!$A:$H,7,FALSE),"") -> 98.1037
A41: =TEXT([1]sheet1!$B$3,"yyyy-mm-dd") -> 2026-08-17 | B41: =IF(LEN(TRIM([2]可交债!A37))=6,TRIM([2]可交债!A37)&".SZ",TRIM([2]可交债!A37)) -> 117230.SZ | C41: =IFERROR(VLOOKUP(LEFT($B41,6)&"*",[2]可交债!$A:$H,2,FALSE),"") -> 25云化KEB | D41: =IFERROR(VLOOKUP(LEFT($B41,6)&"*",[2]可交债!$A:$H,3,FALSE),"") -> 002053.SZ | E41: =IFERROR(VLOOKUP(LEFT($B41,6)&"*",[2]可交债!$A:$H,4,FALSE),"") -> 云南能投 | F41: =SUMPRODUCT((LEFT(TRIM('[3]现券交易信息（逐笔）'!$B$2:$B$500),6)=LEFT($B41,6))*(IFERROR(--SUBSTITUTE('[3]现券交易信息（逐笔）'!$G$2:$G$500,",",""),0)))+SUMIF([1]sheet1!$D$2:$D$500,LEFT($B41,6)&"*",[1]sheet1!$M$2:$M$500) -> 0 | G41: =SUMPRODUCT((LEFT(TRIM('[3]现券交易信息（逐笔）'!$B$2:$B$500),6)=LEFT($B41,6))*(IFERROR(--SUBSTITUTE('[3]现券交易信息（逐笔）'!$F$2:$F$500,",",""),0)*100))+SUMIF([1]sheet1!$D$2:$D$500,LEFT($B41,6)&"*",[1]sheet1!$L$2:$L$500)*100 -> 0 | H41: =IF(G41=0,"",ROUND(F41*10000/G41,4)) | I41: =IFERROR(VLOOKUP(LEFT($B41,6)&"*",[2]可交债!$A:$H,5,FALSE),"") -> 0.1 | J41: =IFERROR(VLOOKUP(LEFT($B41,6)&"*",[2]可交债!$A:$H,6,FALSE),"") -> 1 | K41: =IFERROR(VLOOKUP(LEFT($B41,6)&"*",[2]可交债!$A:$H,7,FALSE),"") -> 15.87 | L41: =IFERROR(VLOOKUP(LEFT($B41,6)&"*",[2]可交债!$A:$H,8,FALSE),"") -> 9.32 | M41: =IFERROR(VLOOKUP(LEFT($B41,6),[4]中证可交换债券估值!$A:$H,5,FALSE),"") -> 105.6304 | N41: =IFERROR(VLOOKUP(LEFT($B41,6),[4]中证可交换债券估值!$A:$H,6,FALSE),"") -> 7.4175 | O41: =IFERROR(VLOOKUP(LEFT($B41,6),[4]中证可交换债券估值!$A:$H,7,FALSE),"") -> 98.2129
A42: =TEXT([1]sheet1!$B$3,"yyyy-mm-dd") -> 2026-08-17 | B42: =IF(LEN(TRIM([2]可交债!A38))=6,TRIM([2]可交债!A38)&".SZ",TRIM([2]可交债!A38)) -> 137193.SH | C42: =IFERROR(VLOOKUP(LEFT($B42,6)&"*",[2]可交债!$A:$H,2,FALSE),"") -> 25浙报EB | D42: =IFERROR(VLOOKUP(LEFT($B42,6)&"*",[2]可交债!$A:$H,3,FALSE),"") -> 600633.SH | E42: =IFERROR(VLOOKUP(LEFT($B42,6)&"*",[2]可交债!$A:$H,4,FALSE),"") -> 浙数文化 | F42: =SUMPRODUCT((LEFT(TRIM('[3]现券交易信息（逐笔）'!$B$2:$B$500),6)=LEFT($B42,6))*(IFERROR(--SUBSTITUTE('[3]现券交易信息（逐笔）'!$G$2:$G$500,",",""),0)))+SUMIF([1]sheet1!$D$2:$D$500,LEFT($B42,6)&"*",[1]sheet1!$M$2:$M$500) -> 0 | G42: =SUMPRODUCT((LEFT(TRIM('[3]现券交易信息（逐笔）'!$B$2:$B$500),6)=LEFT($B42,6))*(IFERROR(--SUBSTITUTE('[3]现券交易信息（逐笔）'!$F$2:$F$500,",",""),0)*100))+SUMIF([1]sheet1!$D$2:$D$500,LEFT($B42,6)&"*",[1]sheet1!$L$2:$L$500)*100 -> 0 | H42: =IF(G42=0,"",ROUND(F42*10000/G42,4)) | I42: =IFERROR(VLOOKUP(LEFT($B42,6)&"*",[2]可交债!$A:$H,5,FALSE),"") -> 0.01 | J42: =IFERROR(VLOOKUP(LEFT($B42,6)&"*",[2]可交债!$A:$H,6,FALSE),"") -> 3 | K42: =IFERROR(VLOOKUP(LEFT($B42,6)&"*",[2]可交债!$A:$H,7,FALSE),"") -> 13.94 | L42: =IFERROR(VLOOKUP(LEFT($B42,6)&"*",[2]可交债!$A:$H,8,FALSE),"") -> 10.74 | M42: =IFERROR(VLOOKUP(LEFT($B42,6),[4]中证可交换债券估值!$A:$H,5,FALSE),"") -> 110.6126 | N42: =IFERROR(VLOOKUP(LEFT($B42,6),[4]中证可交换债券估值!$A:$H,6,FALSE),"") -> 10.2838 | O42: =IFERROR(VLOOKUP(LEFT($B42,6),[4]中证可交换债券估值!$A:$H,7,FALSE),"") -> 100.3288
A43: =TEXT([1]sheet1!$B$3,"yyyy-mm-dd") -> 2026-08-17 | B43: =IF(LEN(TRIM([2]可交债!A39))=6,TRIM([2]可交债!A39)&".SZ",TRIM([2]可交债!A39)) -> 117243.SZ | C43: =IFERROR(VLOOKUP(LEFT($B43,6)&"*",[2]可交债!$A:$H,2,FALSE),"") -> 25众兴EB02 | D43: =IFERROR(VLOOKUP(LEFT($B43,6)&"*",[2]可交债!$A:$H,3,FALSE),"") -> 001203.SZ | E43: =IFERROR(VLOOKUP(LEFT($B43,6)&"*",[2]可交债!$A:$H,4,FALSE),"") -> 大中矿业 | F43: =SUMPRODUCT((LEFT(TRIM('[3]现券交易信息（逐笔）'!$B$2:$B$500),6)=LEFT($B43,6))*(IFERROR(--SUBSTITUTE('[3]现券交易信息（逐笔）'!$G$2:$G$500,",",""),0)))+SUMIF([1]sheet1!$D$2:$D$500,LEFT($B43,6)&"*",[1]sheet1!$M$2:$M$500) -> 0 | G43: =SUMPRODUCT((LEFT(TRIM('[3]现券交易信息（逐笔）'!$B$2:$B$500),6)=LEFT($B43,6))*(IFERROR(--SUBSTITUTE('[3]现券交易信息（逐笔）'!$F$2:$F$500,",",""),0)*100))+SUMIF([1]sheet1!$D$2:$D$500,LEFT($B43,6)&"*",[1]sheet1!$L$2:$L$500)*100 -> 0 | H43: =IF(G43=0,"",ROUND(F43*10000/G43,4)) | I43: =IFERROR(VLOOKUP(LEFT($B43,6)&"*",[2]可交债!$A:$H,5,FALSE),"") -> 0.5 | J43: =IFERROR(VLOOKUP(LEFT($B43,6)&"*",[2]可交债!$A:$H,6,FALSE),"") -> 6 | K43: =IFERROR(VLOOKUP(LEFT($B43,6)&"*",[2]可交债!$A:$H,7,FALSE),"") -> 32.09 | L43: =IFERROR(VLOOKUP(LEFT($B43,6)&"*",[2]可交债!$A:$H,8,FALSE),"") -> 27.94 | M43: =IFERROR(VLOOKUP(LEFT($B43,6),[4]中证可交换债券估值!$A:$H,5,FALSE),"") -> 115.7051 | N43: =IFERROR(VLOOKUP(LEFT($B43,6),[4]中证可交换债券估值!$A:$H,6,FALSE),"") -> 13.34 | O43: =IFERROR(VLOOKUP(LEFT($B43,6),[4]中证可交换债券估值!$A:$H,7,FALSE),"") -> 102.3651
A44: =TEXT([1]sheet1!$B$3,"yyyy-mm-dd") -> 2026-08-17 | B44: =IF(LEN(TRIM([2]可交债!A40))=6,TRIM([2]可交债!A40)&".SZ",TRIM([2]可交债!A40)) -> 117239.SZ | C44: =IFERROR(VLOOKUP(LEFT($B44,6)&"*",[2]可交债!$A:$H,2,FALSE),"") -> 25紫金E1 | D44: =IFERROR(VLOOKUP(LEFT($B44,6)&"*",[2]可交债!$A:$H,3,FALSE),"") -> 002226.SZ | E44: =IFERROR(VLOOKUP(LEFT($B44,6)&"*",[2]可交债!$A:$H,4,FALSE),"") -> 江南化工 | F44: =SUMPRODUCT((LEFT(TRIM('[3]现券交易信息（逐笔）'!$B$2:$B$500),6)=LEFT($B44,6))*(IFERROR(--SUBSTITUTE('[3]现券交易信息（逐笔）'!$G$2:$G$500,",",""),0)))+SUMIF([1]sheet1!$D$2:$D$500,LEFT($B44,6)&"*",[1]sheet1!$M$2:$M$500) -> 0 | G44: =SUMPRODUCT((LEFT(TRIM('[3]现券交易信息（逐笔）'!$B$2:$B$500),6)=LEFT($B44,6))*(IFERROR(--SUBSTITUTE('[3]现券交易信息（逐笔）'!$F$2:$F$500,",",""),0)*100))+SUMIF([1]sheet1!$D$2:$D$500,LEFT($B44,6)&"*",[1]sheet1!$L$2:$L$500)*100 -> 0 | H44: =IF(G44=0,"",ROUND(F44*10000/G44,4)) | I44: =IFERROR(VLOOKUP(LEFT($B44,6)&"*",[2]可交债!$A:$H,5,FALSE),"") -> 0.01 | J44: =IFERROR(VLOOKUP(LEFT($B44,6)&"*",[2]可交债!$A:$H,6,FALSE),"") -> 0 | K44: =IFERROR(VLOOKUP(LEFT($B44,6)&"*",[2]可交债!$A:$H,7,FALSE),"") -> 5.66 | L44: =IFERROR(VLOOKUP(LEFT($B44,6)&"*",[2]可交债!$A:$H,8,FALSE),"") -> 5.13 | M44: =IFERROR(VLOOKUP(LEFT($B44,6),[4]中证可交换债券估值!$A:$H,5,FALSE),"") -> 113.4643 | N44: =IFERROR(VLOOKUP(LEFT($B44,6),[4]中证可交换债券估值!$A:$H,6,FALSE),"") -> 16.7541 | O44: =IFERROR(VLOOKUP(LEFT($B44,6),[4]中证可交换债券估值!$A:$H,7,FALSE),"") -> 96.7102
A45: =TEXT([1]sheet1!B8,"yyyy-mm-dd") -> 2026-08-17 | B45: =IF(LEN(TRIM([1]sheet1!D8))=6,TRIM([1]sheet1!D8)&".SZ",TRIM([1]sheet1!D8)) -> 137208.SH | C45: =IFERROR(VLOOKUP(LEFT($B45,6)&"*",[2]可交债!$A:$H,2,FALSE),"") -> 26AQKEB | D45: =IFERROR(VLOOKUP(LEFT($B45,6)&"*",[2]可交债!$A:$H,3,FALSE),"") -> 600298.SH | E45: =IFERROR(VLOOKUP(LEFT($B45,6)&"*",[2]可交债!$A:$H,4,FALSE),"") -> 安琪酵母 | F45: =[1]sheet1!M8 -> 534.85 | G45: =[1]sheet1!L8*100 -> 50000 | H45: =IF(G45=0,"",ROUND(F45*10000/G45,4)) -> 106.97 | I45: =IFERROR(VLOOKUP(LEFT($B45,6)&"*",[2]可交债!$A:$H,5,FALSE),"") -> 0.01 | J45: =IFERROR(VLOOKUP(LEFT($B45,6)&"*",[2]可交债!$A:$H,6,FALSE),"") -> 0 | K45: =IFERROR(VLOOKUP(LEFT($B45,6)&"*",[2]可交债!$A:$H,7,FALSE),"") -> 60 | L45: =IFERROR(VLOOKUP(LEFT($B45,6)&"*",[2]可交债!$A:$H,8,FALSE),"") -> 41.89 | M45: =IFERROR(VLOOKUP(LEFT($B45,6),[4]中证可交换债券估值!$A:$H,5,FALSE),"") -> 102.4526 | N45: =IFERROR(VLOOKUP(LEFT($B45,6),[4]中证可交换债券估值!$A:$H,6,FALSE),"") -> 7.3307 | O45: =IFERROR(VLOOKUP(LEFT($B45,6),[4]中证可交换债券估值!$A:$H,7,FALSE),"") -> 95.1219
A46: =TEXT([1]sheet1!B9,"yyyy-mm-dd") -> 2026-08-17 | B46: =IF(LEN(TRIM([1]sheet1!D9))=6,TRIM([1]sheet1!D9)&".SZ",TRIM([1]sheet1!D9)) -> 137208.SH | C46: =IFERROR(VLOOKUP(LEFT($B46,6)&"*",[2]可交债!$A:$H,2,FALSE),"") -> 26AQKEB | D46: =IFERROR(VLOOKUP(LEFT($B46,6)&"*",[2]可交债!$A:$H,3,FALSE),"") -> 600298.SH | E46: =IFERROR(VLOOKUP(LEFT($B46,6)&"*",[2]可交债!$A:$H,4,FALSE),"") -> 安琪酵母 | F46: =[1]sheet1!M9 -> 534.85 | G46: =[1]sheet1!L9*100 -> 50000 | H46: =IF(G46=0,"",ROUND(F46*10000/G46,4)) -> 106.97 | I46: =IFERROR(VLOOKUP(LEFT($B46,6)&"*",[2]可交债!$A:$H,5,FALSE),"") -> 0.01 | J46: =IFERROR(VLOOKUP(LEFT($B46,6)&"*",[2]可交债!$A:$H,6,FALSE),"") -> 0 | K46: =IFERROR(VLOOKUP(LEFT($B46,6)&"*",[2]可交债!$A:$H,7,FALSE),"") -> 60 | L46: =IFERROR(VLOOKUP(LEFT($B46,6)&"*",[2]可交债!$A:$H,8,FALSE),"") -> 41.89 | M46: =IFERROR(VLOOKUP(LEFT($B46,6),[4]中证可交换债券估值!$A:$H,5,FALSE),"") -> 102.4526 | N46: =IFERROR(VLOOKUP(LEFT($B46,6),[4]中证可交换债券估值!$A:$H,6,FALSE),"") -> 7.3307 | O46: =IFERROR(VLOOKUP(LEFT($B46,6),[4]中证可交换债券估值!$A:$H,7,FALSE),"") -> 95.1219
...
